Workbook

Sheet Summary
A1: FX control variables: summary
A2: Daily time series, January 2000 to 14 October 2026. Prepared 14 Oct 2026 for the Fintech Practicum.
A4: What's done
A5: • Downloaded the source files from FRED, the RBNZ, ALFRED (St. Louis Fed) and Stats NZ through the Claude desktop browser, then read and processed them.
A6: • Built one row per weekday from 3 Jan 2000 to 14 Oct 2026. Missing values are left blank, not filled in.
A7: • Wrote the differentials and release-day dummies as Excel formulas, so they update if inputs change.
A8: • Checked the workbook: formulas recalculate with no errors; the differentials match the source data exactly; release counts are 321 US CPI, 321 payrolls and 112 NZ releases.
A10: What's in the workbook
A11: Summary | B11: This page.
A12: Daily_Data | B12: The time series: one row per weekday with the US 2y, NZ 2y swap, NZ 2y government yields, both differentials, VIX and the release-day dummies.
A13: Notes | B13: Source, coverage and caveats for each column, plus the NZ calendar coverage-start setting (cell B5).
A14: Release_Calendar | B14: Every release date found, with local, UTC and New York times. The release-day dummies read from this sheet.
A15: Splice_Check | B15: How closely the NZ swap and NZ government bond yield match over 2011–2017.
A17: Status by variable
A18: VIX | B18: COMPLETE. 3 Jan 2000 to 13 Oct 2026. The only blanks are US market holidays.
A19: US 2-year Treasury | B19: COMPLETE. 3 Jan 2000 to 9 Oct 2026. The only blanks are US market holidays.
A20: NZ–US 2y differential | B20: PARTIAL. Arman's version (NZ swap minus US Treasury) starts 5 Jan 2011, because the RBNZ has no free daily swap data before then. For 2000–2010 the NZ 2y government bond yield is spliced in, and nz_leg_is_govt_bond = 1 marks those rows. Caveats: the bond yield's daily moves track the swap less closely (correlation 0.53 vs 0.96 in levels), and the bond flows we study could move it. Bloomberg or LSEG would have the real pre-2011 swap history.
A21: US release days | B21: COMPLETE. CPI and payrolls from 2000, including the 2025 shutdown delays.
A22: NZ release days | B22: PARTIAL. GDP, CPI and labour market from mid-2017 only. Before 15 Jun 2017 the NZ columns are blank, not 0. Stats NZ closed its archive site; no free source found for 2000–2007. Bloomberg release-date history would fill the whole gap.
A24: Timing
A25: NZ data comes out at 10:45am NZ time, which is the previous evening in New York. If NZD/USD prices are taken at the New York close, consider moving the NZ release dummies one day earlier. Release_Calendar has UTC and New York timestamps for this.
A27: Text for the team
A28: VIX and US release days (CPI and payrolls) are complete for Jan 2000 to present. The NZ–US 2y differential has gaps: the RBNZ's daily NZ 2y swap only starts in Jan 2011. I've filled 2000–2010 with the NZ 2y government bond yield and flagged those rows, with caveats in the file. NZ release dates (GDP, CPI, labour market) only exist from mid-2017 because Stats NZ closed its archive. Does anyone have Bloomberg access? It would give us the pre-2011 NZD 2y swap and the NZ release dates for 2000–2017.
A30: Sources
A31: FRED DGS2 | B31: https://fred.stlouisfed.org/series/DGS2
A32: FRED VIXCLS | B32: https://fred.stlouisfed.org/series/VIXCLS
A33: RBNZ B2 wholesale interest rates | B33: https://www.rbnz.govt.nz/statistics/series/exchange-and-interest-rates/wholesale-interest-rates
A34: ALFRED PAYEMS (payrolls release dates) | B34: https://alfred.stlouisfed.org/series?seid=PAYEMS
A35: ALFRED CPIAUCNS (CPI release dates) | B35: https://alfred.stlouisfed.org/series?seid=CPIAUCNS
A36: Stats NZ A–Z of information releases | B36: https://www.stats.govt.nz/az-of-information-releases
A37: Stats NZ archive website notice | B37: https://www.stats.govt.nz/about-us/stats-nz-archive-website/

Sheet Notes
A1: FX control variables: data pull, January 2000 to 14 October 2026
A2: Prepared 14 Oct 2026 for the Fintech Practicum. Sources and gaps are listed below.
A4: Settings
A5: NZ release calendar coverage start (NZ dummies are blank before this date) | B5: 42901
A7: Variable | B7: Status / source / notes
A8: 1. Monetary policy: NZ–US 2-year differential
A9: us_2y_treasury | B9: COMPLETE 3 Jan 2000 to 9 Oct 2026. FRED DGS2 (Board of Governors H.15), daily. Blank days are US market holidays.
A10: nz_2y_swap | B10: PARTIAL: 5 Jan 2011 to 13 Oct 2026. RBNZ B2 "Daily close" files (1985–2017 and 2018–current), series INM.DS02.NZZC. RBNZ publishes no daily 2-year swap before 5 Jan 2011. We checked the current files and the unlinked legacy B2 files (hb2-daily.xlsx, hb2-daily-1985-2017.xlsx, hb2-monthly.xlsx); none has swaps before 2011.
A11: nz_2y_govt_11am | B11: Fallback for 2000–2010: RBNZ legacy B2 daily file (hb2-daily-1985-2017.xlsx), series INM.DG102.N, the 2-year government bond yield at about 11am. Covers 2000–2017 (4,232 of 4,523 days).
A12: nz_2y_govt_close | B12: Reference only: RBNZ B2 closing 2-year government bond yield (INM.DG102.NZZCF), 29 Jan 2009 onward, with gaps.
A13: diff_2y_swap_minus_ust | B13: Arman's specification: NZ 2y swap minus US 2y Treasury. Available from 5 Jan 2011 only. Excel formula.
A14: nz_2y_spliced / diff_2y_spliced | B14: PROPOSED MERGE for the full window: NZ 2y swap from 5 Jan 2011, NZ 2y government bond yield (11am) before that, minus the US 2y. nz_leg_is_govt_bond = 1 marks the pre-2011 rows. See the Splice_Check sheet.
A15: Why the merge is defensible | B15: Over the 2011–2017 overlap the two NZ series move almost one-for-one in levels (correlation 0.96) and both track RBNZ policy expectations at the 2-year horizon. Include nz_leg_is_govt_bond in the regression (or interact it with the differential): it absorbs the level gap between the instruments, which averaged +0.21 pp (sd 0.14) in 2011–2017.
A16: Caveats on the merge | B16: (a) Daily changes match less well: correlation 0.53 for the 11am govt yield vs the swap close, 0.78 close-to-close. So the pre-2011 series is noisier as a daily control. (b) Arman preferred the swap because government bond yields can be moved by the bond flows we study. That concern applies to 2000–2010 under the merge. (c) Robustness check: re-run on the 2011+ sample with the pure swap differential.
A17: Better fix if the team has Bloomberg/LSEG | B17: A daily NZD 2y swap history before 2011 exists in Bloomberg and LSEG (Refinitiv); LSEG is RBNZ's own data source. Pulling it there would remove the need for the merge.
A18: 2. Real growth: major data release day
A19: rel_us_cpi | B19: COMPLETE 2000 to 14 Oct 2026. Release dates are the ALFRED vintage dates of CPIAUCNS (non-seasonally-adjusted CPI is only revised when a new CPI comes out, so each vintage date is a release day). One duplicate vintage that was not a release was removed: 28 Sep 2000. The 2025 shutdown is reflected: there was no October 2025 CPI release, and the 24 Oct and 18 Dec 2025 releases are included.
A20: rel_us_nfp | B20: COMPLETE 2000 to 2 Oct 2026. Release dates are the ALFRED vintage dates of PAYEMS (Employment Situation report). Three correction vintages that were not report days were removed: 9 Dec 2002, 10 Oct 2003, 11 May 2020. The delayed shutdown reports (20 Nov and 16 Dec 2025) are included.
A21: rel_nz_cpi / rel_nz_gdp / rel_nz_labour | B21: PARTIAL: mid-2017 to Sep 2026 only (GDP from 15 Jun 2017, CPI from 18 Jul 2017, labour market from 2 Aug 2017). Source: Stats NZ information-release listings, with dates and 10:45am NZT times. Before 15 Jun 2017 these columns are BLANK, not 0, so missing dates are not mistaken for "no release".
A22: Why NZ 2000–2017 is missing | B22: Stats NZ has closed its archive website (archive.stats.govt.nz), where the pre-2017 releases lived. Internet Archive copies of the release pages exist for about 2008–2017 and include the embargo date, but the archive limits how fast pages can be requested, and that pull was stopped. For 2000–2007 we found no free source.
A23: Options to fill NZ 2000–2017 | B23: (1) Bloomberg: the release-date history field (ECO_RELEASE_DT) for the NZ CPI, GDP and unemployment-rate tickers covers back to the 1990s. This is the cleanest fix. (2) Resume the Internet Archive pull for 2008–2017 (slow; leaves 2000–2007 open). (3) Ask Stats NZ (info@stats.govt.nz) for its historical release calendar.
A24: major_release_day | B24: Equals 1 if any US or NZ release falls on that date. Before 15 Jun 2017 it reflects US releases only, so use the NZ-specific columns or restrict the sample when NZ releases matter.
A25: Timing caution | B25: NZ releases come out at 10:45am NZT, which is the previous evening in New York (about 5:45pm EDT or 4:45pm EST). Dummies are dated by the local release date. If NZD/USD is measured at the New York close, consider shifting the NZ dummies one day earlier. Release_Calendar includes UTC and New York timestamps for this.
A26: 3. Currency risk: VIX
A27: vix | B27: COMPLETE 3 Jan 2000 to 13 Oct 2026. FRED VIXCLS (CBOE), daily close. Blank days are US market holidays.
A29: General | B29: Daily_Data has one row per weekday. Blanks are left blank: no forward-filling or interpolation, so the team can choose its own rule. The differential and release-day columns are Excel formulas.
A30: Raw files | B30: FRED CSVs (DGS2, VIXCLS), RBNZ B2 xlsx files, ALFRED vintage-date lists and the Stats NZ release list were downloaded on 14 Oct 2026 and are available on request.

Sheet Regression Control Panel
A1: date | B1: vix | C1: treasury_swap_merged | D1: us_release
A2: =Daily_Data!A2 -> 36528 | B2: =Daily_Data!J2 -> 24.21 | C2: =Daily_Data!I2 | D2: =if(sum(Daily_Data!K2:L2)>0,1,0) -> 0
A3: =Daily_Data!A3 -> 36529 | B3: =Daily_Data!J3 -> 27.01 | C3: =Daily_Data!I3 | D3: =if(sum(Daily_Data!K3:L3)>0,1,0) -> 0
A4: =Daily_Data!A4 -> 36530 | B4: =Daily_Data!J4 -> 26.41 | C4: =Daily_Data!I4 -> 0.31 | D4: =if(sum(Daily_Data!K4:L4)>0,1,0) -> 0
A5: =Daily_Data!A5 -> 36531 | B5: =Daily_Data!J5 -> 25.73 | C5: =Daily_Data!I5 -> 0.41 | D5: =if(sum(Daily_Data!K5:L5)>0,1,0) -> 0
A6: =Daily_Data!A6 -> 36532 | B6: =Daily_Data!J6 -> 21.72 | C6: =Daily_Data!I6 -> 0.47 | D6: =if(sum(Daily_Data!K6:L6)>0,1,0) -> 1
A7: =Daily_Data!A7 -> 36535 | B7: =Daily_Data!J7 -> 21.71 | C7: =Daily_Data!I7 -> 0.38 | D7: =if(sum(Daily_Data!K7:L7)>0,1,0) -> 0
A8: =Daily_Data!A8 -> 36536 | B8: =Daily_Data!J8 -> 22.5 | C8: =Daily_Data!I8 -> 0.31 | D8: =if(sum(Daily_Data!K8:L8)>0,1,0) -> 0
A9: =Daily_Data!A9 -> 36537 | B9: =Daily_Data!J9 -> 22.84 | C9: =Daily_Data!I9 -> 0.39 | D9: =if(sum(Daily_Data!K9:L9)>0,1,0) -> 0
A10: =Daily_Data!A10 -> 36538 | B10: =Daily_Data!J10 -> 21.71 | C10: =Daily_Data!I10 -> 0.48 | D10: =if(sum(Daily_Data!K10:L10)>0,1,0) -> 0
A11: =Daily_Data!A11 -> 36539 | B11: =Daily_Data!J11 -> 19.66 | C11: =Daily_Data!I11 -> 0.38 | D11: =if(sum(Daily_Data!K11:L11)>0,1,0) -> 1
A12: =Daily_Data!A12 -> 36542 | B12: =Daily_Data!J12 | C12: =Daily_Data!I12 | D12: =if(sum(Daily_Data!K12:L12)>0,1,0) -> 0
A13: =Daily_Data!A13 -> 36543 | B13: =Daily_Data!J13 -> 21.5 | C13: =Daily_Data!I13 -> 0.42 | D13: =if(sum(Daily_Data!K13:L13)>0,1,0) -> 0
... A6989: =Daily_Data!A6989 -> 46309 | B6989: =Daily_Data!J6989 | C6989: =Daily_Data!I6989 | D6989: =if(sum(Daily_Data!K6989:L6989)>0,1,0) -> 1
A6990: =Daily_Data!A6990 | B6990: =Daily_Data!J6990 | C6990: =Daily_Data!I6990
A6991: =Daily_Data!A6991 | B6991: =Daily_Data!J6991 | C6991: =Daily_Data!I6991
A6992: =Daily_Data!A6992 | B6992: =Daily_Data!J6992 | C6992: =Daily_Data!I6992
A6993: =Daily_Data!A6993 | B6993: =Daily_Data!J6993 | C6993: =Daily_Data!I6993
A6994: =Daily_Data!A6994 | B6994: =Daily_Data!J6994 | C6994: =Daily_Data!I6994
A6995: =Daily_Data!A6995 | B6995: =Daily_Data!J6995 | C6995: =Daily_Data!I6995
A6996: =Daily_Data!A6996 | B6996: =Daily_Data!J6996 | C6996: =Daily_Data!I6996
A6997: =Daily_Data!A6997 | B6997: =Daily_Data!J6997 | C6997: =Daily_Data!I6997
A6998: =Daily_Data!A6998 | B6998: =Daily_Data!J6998 | C6998: =Daily_Data!I6998
A6999: =Daily_Data!A6999 | B6999: =Daily_Data!J6999 | C6999: =Daily_Data!I6999

Sheet Daily_Data
A1: date | B1: us_2y_treasury | C1: nz_2y_swap | D1: nz_2y_govt_11am | E1: nz_2y_govt_close | F1: diff_2y_swap_minus_ust | G1: nz_2y_spliced | H1: nz_leg_is_govt_bond | I1: diff_2y_spliced | J1: vix | K1: rel_us_cpi | L1: rel_us_nfp | M1: rel_nz_cpi | N1: rel_nz_gdp | O1: rel_nz_labour | P1: major_release_day
A2: 36528 | B2: 6.38 | F2: =IF(OR(B2="",C2=""),"",C2-B2) | G2: =IF(H2=1,IF(D2="","",D2),IF(C2="","",C2)) | H2: 1 | I2: =IF(OR(B2="",G2=""),"",G2-B2) | J2: 24.21 | K2: =IF(COUNTIFS(Release_Calendar!$A$2:$A$755,"US_CPI",Release_Calendar!$B$2:$B$755,$A2)>0,1,0) -> 0 | L2: =IF(COUNTIFS(Release_Calendar!$A$2:$A$755,"US_NFP",Release_Calendar!$B$2:$B$755,$A2)>0,1,0) -> 0 | M2: =IF($A2<Notes!$B$5,"",IF(COUNTIFS(Release_Calendar!$A$2:$A$755,"NZ_CPI",Release_Calendar!$B$2:$B$755,$A2)>0,1,0)) | N2: =IF($A2<Notes!$B$5,"",IF(COUNTIFS(Release_Calendar!$A$2:$A$755,"NZ_GDP",Release_Calendar!$B$2:$B$755,$A2)>0,1,0)) | O2: =IF($A2<Notes!$B$5,"",IF(COUNTIFS(Release_Calendar!$A$2:$A$755,"NZ_LABOUR",Release_Calendar!$B$2:$B$755,$A2)>0,1,0)) | P2: =IF(SUM(K2:O2)>0,1,0) -> 0
A3: 36529 | B3: 6.3 | F3: =IF(OR(B3="",C3=""),"",C3-B3) | G3: =IF(H3=1,IF(D3="","",D3),IF(C3="","",C3)) | H3: 1 | I3: =IF(OR(B3="",G3=""),"",G3-B3) | J3: 27.01 | K3: =IF(COUNTIFS(Release_Calendar!$A$2:$A$755,"US_CPI",Release_Calendar!$B$2:$B$755,$A3)>0,1,0) -> 0 | L3: =IF(COUNTIFS(Release_Calendar!$A$2:$A$755,"US_NFP",Release_Calendar!$B$2:$B$755,$A3)>0,1,0) -> 0 | M3: =IF($A3<Notes!$B$5,"",IF(COUNTIFS(Release_Calendar!$A$2:$A$755,"NZ_CPI",Release_Calendar!$B$2:$B$755,$A3)>0,1,0)) | N3: =IF($A3<Notes!$B$5,"",IF(COUNTIFS(Release_Calendar!$A$2:$A$755,"NZ_GDP",Release_Calendar!$B$2:$B$755,$A3)>0,1,0)) | O3: =IF($A3<Notes!$B$5,"",IF(COUNTIFS(Release_Calendar!$A$2:$A$755,"NZ_LABOUR",Release_Calendar!$B$2:$B$755,$A3)>0,1,0)) | P3: =IF(SUM(K3:O3)>0,1,0) -> 0
A4: 36530 | B4: 6.38 | D4: 6.69 | F4: =IF(OR(B4="",C4=""),"",C4-B4) | G4: =IF(H4=1,IF(D4="","",D4),IF(C4="","",C4)) -> 6.69 | H4: 1 | I4: =IF(OR(B4="",G4=""),"",G4-B4) -> 0.31 | J4: 26.41 | K4: =IF(COUNTIFS(Release_Calendar!$A$2:$A$755,"US_CPI",Release_Calendar!$B$2:$B$755,$A4)>0,1,0) -> 0 | L4: =IF(COUNTIFS(Release_Calendar!$A$2:$A$755,"US_NFP",Release_Calendar!$B$2:$B$755,$A4)>0,1,0) -> 0 | M4: =IF($A4<Notes!$B$5,"",IF(COUNTIFS(Release_Calendar!$A$2:$A$755,"NZ_CPI",Release_Calendar!$B$2:$B$755,$A4)>0,1,0)) | N4: =IF($A4<Notes!$B$5,"",IF(COUNTIFS(Release_Calendar!$A$2:$A$755,"NZ_GDP",Release_Calendar!$B$2:$B$755,$A4)>0,1,0)) | O4: =IF($A4<Notes!$B$5,"",IF(COUNTIFS(Release_Calendar!$A$2:$A$755,"NZ_LABOUR",Release_Calendar!$B$2:$B$755,$A4)>0,1,0)) | P4: =IF(SUM(K4:O4)>0,1,0) -> 0
A5: 36531 | B5: 6.35 | D5: 6.76 | F5: =IF(OR(B5="",C5=""),"",C5-B5) | G5: =IF(H5=1,IF(D5="","",D5),IF(C5="","",C5)) -> 6.76 | H5: 1 | I5: =IF(OR(B5="",G5=""),"",G5-B5) -> 0.41 | J5: 25.73 | K5: =IF(COUNTIFS(Release_Calendar!$A$2:$A$755,"US_CPI",Release_Calendar!$B$2:$B$755,$A5)>0,1,0) -> 0 | L5: =IF(COUNTIFS(Release_Calendar!$A$2:$A$755,"US_NFP",Release_Calendar!$B$2:$B$755,$A5)>0,1,0) -> 0 | M5: =IF($A5<Notes!$B$5,"",IF(COUNTIFS(Release_Calendar!$A$2:$A$755,"NZ_CPI",Release_Calendar!$B$2:$B$755,$A5)>0,1,0)) | N5: =IF($A5<Notes!$B$5,"",IF(COUNTIFS(Release_Calendar!$A$2:$A$755,"NZ_GDP",Release_Calendar!$B$2:$B$755,$A5)>0,1,0)) | O5: =IF($A5<Notes!$B$5,"",IF(COUNTIFS(Release_Calendar!$A$2:$A$755,"NZ_LABOUR",Release_Calendar!$B$2:$B$755,$A5)>0,1,0)) | P5: =IF(SUM(K5:O5)>0,1,0) -> 0
A6: 36532 | B6: 6.31 | D6: 6.78 | F6: =IF(OR(B6="",C6=""),"",C6-B6) | G6: =IF(H6=1,IF(D6="","",D6),IF(C6="","",C6)) -> 6.78 | H6: 1 | I6: =IF(OR(B6="",G6=""),"",G6-B6) -> 0.47 | J6: 21.72 | K6: =IF(COUNTIFS(Release_Calendar!$A$2:$A$755,"US_CPI",Release_Calendar!$B$2:$B$755,$A6)>0,1,0) -> 0 | L6: =IF(COUNTIFS(Release_Calendar!$A$2:$A$755,"US_NFP",Release_Calendar!$B$2:$B$755,$A6)>0,1,0) -> 1 | M6: =IF($A6<Notes!$B$5,"",IF(COUNTIFS(Release_Calendar!$A$2:$A$755,"NZ_CPI",Release_Calendar!$B$2:$B$755,$A6)>0,1,0)) | N6: =IF($A6<Notes!$B$5,"",IF(COUNTIFS(Release_Calendar!$A$2:$A$755,"NZ_GDP",Release_Calendar!$B$2:$B$755,$A6)>0,1,0)) | O6: =IF($A6<Notes!$B$5,"",IF(COUNTIFS(Release_Calendar!$A$2:$A$755,"NZ_LABOUR",Release_Calendar!$B$2:$B$755,$A6)>0,1,0)) | P6: =IF(SUM(K6:O6)>0,1,0) -> 1
A7: 36535 | B7: 6.38 | D7: 6.76 | F7: =IF(OR(B7="",C7=""),"",C7-B7) | G7: =IF(H7=1,IF(D7="","",D7),IF(C7="","",C7)) -> 6.76 | H7: 1 | I7: =IF(OR(B7="",G7=""),"",G7-B7) -> 0.38 | J7: 21.71 | K7: =IF(COUNTIFS(Release_Calendar!$A$2:$A$755,"US_CPI",Release_Calendar!$B$2:$B$755,$A7)>0,1,0) -> 0 | L7: =IF(COUNTIFS(Release_Calendar!$A$2:$A$755,"US_NFP",Release_Calendar!$B$2:$B$755,$A7)>0,1,0) -> 0 | M7: =IF($A7<Notes!$B$5,"",IF(COUNTIFS(Release_Calendar!$A$2:$A$755,"NZ_CPI",Release_Calendar!$B$2:$B$755,$A7)>0,1,0)) | N7: =IF($A7<Notes!$B$5,"",IF(COUNTIFS(Release_Calendar!$A$2:$A$755,"NZ_GDP",Release_Calendar!$B$2:$B$755,$A7)>0,1,0)) | O7: =IF($A7<Notes!$B$5,"",IF(COUNTIFS(Release_Calendar!$A$2:$A$755,"NZ_LABOUR",Release_Calendar!$B$2:$B$755,$A7)>0,1,0)) | P7: =IF(SUM(K7:O7)>0,1,0) -> 0
A8: 36536 | B8: 6.45 | D8: 6.76 | F8: =IF(OR(B8="",C8=""),"",C8-B8) | G8: =IF(H8=1,IF(D8="","",D8),IF(C8="","",C8)) -> 6.76 | H8: 1 | I8: =IF(OR(B8="",G8=""),"",G8-B8) -> 0.31 | J8: 22.5 | K8: =IF(COUNTIFS(Release_Calendar!$A$2:$A$755,"US_CPI",Release_Calendar!$B$2:$B$755,$A8)>0,1,0) -> 0 | L8: =IF(COUNTIFS(Release_Calendar!$A$2:$A$755,"US_NFP",Release_Calendar!$B$2:$B$755,$A8)>0,1,0) -> 0 | M8: =IF($A8<Notes!$B$5,"",IF(COUNTIFS(Release_Calendar!$A$2:$A$755,"NZ_CPI",Release_Calendar!$B$2:$B$755,$A8)>0,1,0)) | N8: =IF($A8<Notes!$B$5,"",IF(COUNTIFS(Release_Calendar!$A$2:$A$755,"NZ_GDP",Release_Calendar!$B$2:$B$755,$A8)>0,1,0)) | O8: =IF($A8<Notes!$B$5,"",IF(COUNTIFS(Release_Calendar!$A$2:$A$755,"NZ_LABOUR",Release_Calendar!$B$2:$B$755,$A8)>0,1,0)) | P8: =IF(SUM(K8:O8)>0,1,0) -> 0
A9: 36537 | B9: 6.49 | D9: 6.88 | F9: =IF(OR(B9="",C9=""),"",C9-B9) | G9: =IF(H9=1,IF(D9="","",D9),IF(C9="","",C9)) -> 6.88 | H9: 1 | I9: =IF(OR(B9="",G9=""),"",G9-B9) -> 0.39 | J9: 22.84 | K9: =IF(COUNTIFS(Release_Calendar!$A$2:$A$755,"US_CPI",Release_Calendar!$B$2:$B$755,$A9)>0,1,0) -> 0 | L9: =IF(COUNTIFS(Release_Calendar!$A$2:$A$755,"US_NFP",Release_Calendar!$B$2:$B$755,$A9)>0,1,0) -> 0 | M9: =IF($A9<Notes!$B$5,"",IF(COUNTIFS(Release_Calendar!$A$2:$A$755,"NZ_CPI",Release_Calendar!$B$2:$B$755,$A9)>0,1,0)) | N9: =IF($A9<Notes!$B$5,"",IF(COUNTIFS(Release_Calendar!$A$2:$A$755,"NZ_GDP",Release_Calendar!$B$2:$B$755,$A9)>0,1,0)) | O9: =IF($A9<Notes!$B$5,"",IF(COUNTIFS(Release_Calendar!$A$2:$A$755,"NZ_LABOUR",Release_Calendar!$B$2:$B$755,$A9)>0,1,0)) | P9: =IF(SUM(K9:O9)>0,1,0) -> 0
A10: 36538 | B10: 6.4 | D10: 6.88 | F10: =IF(OR(B10="",C10=""),"",C10-B10) | G10: =IF(H10=1,IF(D10="","",D10),IF(C10="","",C10)) -> 6.88 | H10: 1 | I10: =IF(OR(B10="",G10=""),"",G10-B10) -> 0.48 | J10: 21.71 | K10: =IF(COUNTIFS(Release_Calendar!$A$2:$A$755,"US_CPI",Release_Calendar!$B$2:$B$755,$A10)>0,1,0) -> 0 | L10: =IF(COUNTIFS(Release_Calendar!$A$2:$A$755,"US_NFP",Release_Calendar!$B$2:$B$755,$A10)>0,1,0) -> 0 | M10: =IF($A10<Notes!$B$5,"",IF(COUNTIFS(Release_Calendar!$A$2:$A$755,"NZ_CPI",Release_Calendar!$B$2:$B$755,$A10)>0,1,0)) | N10: =IF($A10<Notes!$B$5,"",IF(COUNTIFS(Release_Calendar!$A$2:$A$755,"NZ_GDP",Release_Calendar!$B$2:$B$755,$A10)>0,1,0)) | O10: =IF($A10<Notes!$B$5,"",IF(COUNTIFS(Release_Calendar!$A$2:$A$755,"NZ_LABOUR",Release_Calendar!$B$2:$B$755,$A10)>0,1,0)) | P10: =IF(SUM(K10:O10)>0,1,0) -> 0
A11: 36539 | B11: 6.44 | D11: 6.82 | F11: =IF(OR(B11="",C11=""),"",C11-B11) | G11: =IF(H11=1,IF(D11="","",D11),IF(C11="","",C11)) -> 6.82 | H11: 1 | I11: =IF(OR(B11="",G11=""),"",G11-B11) -> 0.38 | J11: 19.66 | K11: =IF(COUNTIFS(Release_Calendar!$A$2:$A$755,"US_CPI",Release_Calendar!$B$2:$B$755,$A11)>0,1,0) -> 1 | L11: =IF(COUNTIFS(Release_Calendar!$A$2:$A$755,"US_NFP",Release_Calendar!$B$2:$B$755,$A11)>0,1,0) -> 0 | M11: =IF($A11<Notes!$B$5,"",IF(COUNTIFS(Release_Calendar!$A$2:$A$755,"NZ_CPI",Release_Calendar!$B$2:$B$755,$A11)>0,1,0)) | N11: =IF($A11<Notes!$B$5,"",IF(COUNTIFS(Release_Calendar!$A$2:$A$755,"NZ_GDP",Release_Calendar!$B$2:$B$755,$A11)>0,1,0)) | O11: =IF($A11<Notes!$B$5,"",IF(COUNTIFS(Release_Calendar!$A$2:$A$755,"NZ_LABOUR",Release_Calendar!$B$2:$B$755,$A11)>0,1,0)) | P11: =IF(SUM(K11:O11)>0,1,0) -> 1
A12: 36542 | D12: 6.86 | F12: =IF(OR(B12="",C12=""),"",C12-B12) | G12: =IF(H12=1,IF(D12="","",D12),IF(C12="","",C12)) -> 6.86 | H12: 1 | I12: =IF(OR(B12="",G12=""),"",G12-B12) | K12: =IF(COUNTIFS(Release_Calendar!$A$2:$A$755,"US_CPI",Release_Calendar!$B$2:$B$755,$A12)>0,1,0) -> 0 | L12: =IF(COUNTIFS(Release_Calendar!$A$2:$A$755,"US_NFP",Release_Calendar!$B$2:$B$755,$A12)>0,1,0) -> 0 | M12: =IF($A12<Notes!$B$5,"",IF(COUNTIFS(Release_Calendar!$A$2:$A$755,"NZ_CPI",Release_Calendar!$B$2:$B$755,$A12)>0,1,0)) | N12: =IF($A12<Notes!$B$5,"",IF(COUNTIFS(Release_Calendar!$A$2:$A$755,"NZ_GDP",Release_Calendar!$B$2:$B$755,$A12)>0,1,0)) | O12: =IF($A12<Notes!$B$5,"",IF(COUNTIFS(Release_Calendar!$A$2:$A$755,"NZ_LABOUR",Release_Calendar!$B$2:$B$755,$A12)>0,1,0)) | P12: =IF(SUM(K12:O12)>0,1,0) -> 0
A13: 36543 | B13: 6.47 | D13: 6.89 | F13: =IF(OR(B13="",C13=""),"",C13-B13) | G13: =IF(H13=1,IF(D13="","",D13),IF(C13="","",C13)) -> 6.89 | H13: 1 | I13: =IF(OR(B13="",G13=""),"",G13-B13) -> 0.42 | J13: 21.5 | K13: =IF(COUNTIFS(Release_Calendar!$A$2:$A$755,"US_CPI",Release_Calendar!$B$2:$B$755,$A13)>0,1,0) -> 0 | L13: =IF(COUNTIFS(Release_Calendar!$A$2:$A$755,"US_NFP",Release_Calendar!$B$2:$B$755,$A13)>0,1,0) -> 0 | M13: =IF($A13<Notes!$B$5,"",IF(COUNTIFS(Release_Calendar!$A$2:$A$755,"NZ_CPI",Release_Calendar!$B$2:$B$755,$A13)>0,1,0)) | N13: =IF($A13<Notes!$B$5,"",IF(COUNTIFS(Release_Calendar!$A$2:$A$755,"NZ_GDP",Release_Calendar!$B$2:$B$755,$A13)>0,1,0)) | O13: =IF($A13<Notes!$B$5,"",IF(COUNTIFS(Release_Calendar!$A$2:$A$755,"NZ_LABOUR",Release_Calendar!$B$2:$B$755,$A13)>0,1,0)) | P13: =IF(SUM(K13:O13)>0,1,0) -> 0
A14: 36544 | B14: 6.46 | D14: 7.02 | F14: =IF(OR(B14="",C14=""),"",C14-B14) | G14: =IF(H14=1,IF(D14="","",D14),IF(C14="","",C14)) -> 7.02 | H14: 1 | I14: =IF(OR(B14="",G14=""),"",G14-B14) -> 0.56 | J14: 21.72 | K14: =IF(COUNTIFS(Release_Calendar!$A$2:$A$755,"US_CPI",Release_Calendar!$B$2:$B$755,$A14)>0,1,0) -> 0 | L14: =IF(COUNTIFS(Release_Calendar!$A$2:$A$755,"US_NFP",Release_Calendar!$B$2:$B$755,$A14)>0,1,0) -> 0 | M14: =IF($A14<Notes!$B$5,"",IF(COUNTIFS(Release_Calendar!$A$2:$A$755,"NZ_CPI",Release_Calendar!$B$2:$B$755,$A14)>0,1,0)) | N14: =IF($A14<Notes!$B$5,"",IF(COUNTIFS(Release_Calendar!$A$2:$A$755,"NZ_GDP",Release_Calendar!$B$2:$B$755,$A14)>0,1,0)) | O14: =IF($A14<Notes!$B$5,"",IF(COUNTIFS(Release_Calendar!$A$2:$A$755,"NZ_LABOUR",Release_Calendar!$B$2:$B$755,$A14)>0,1,0)) | P14: =IF(SUM(K14:O14)>0,1,0) -> 0
A15: 36545 | B15: 6.49 | D15: 6.95 | F15: =IF(OR(B15="",C15=""),"",C15-B15) | G15: =IF(H15=1,IF(D15="","",D15),IF(C15="","",C15)) -> 6.95 | H15: 1 | I15: =IF(OR(B15="",G15=""),"",G15-B15) -> 0.46 | J15: 21.75 | K15: =IF(COUNTIFS(Release_Calendar!$A$2:$A$755,"US_CPI",Release_Calendar!$B$2:$B$755,$A15)>0,1,0) -> 0 | L15: =IF(COUNTIFS(Release_Calendar!$A$2:$A$755,"US_NFP",Release_Calendar!$B$2:$B$755,$A15)>0,1,0) -> 0 | M15: =IF($A15<Notes!$B$5,"",IF(COUNTIFS(Release_Calendar!$A$2:$A$755,"NZ_CPI",Release_Calendar!$B$2:$B$755,$A15)>0,1,0)) | N15: =IF($A15<Notes!$B$5,"",IF(COUNTIFS(Release_Calendar!$A$2:$A$755,"NZ_GDP",Release_Calendar!$B$2:$B$755,$A15)>0,1,0)) | O15: =IF($A15<Notes!$B$5,"",IF(COUNTIFS(Release_Calendar!$A$2:$A$755,"NZ_LABOUR",Release_Calendar!$B$2:$B$755,$A15)>0,1,0)) | P15: =IF(SUM(K15:O15)>0,1,0) -> 0
A16: 36546 | B16: 6.48 | D16: 6.96 | F16: =IF(OR(B16="",C16=""),"",C16-B16) | G16: =IF(H16=1,IF(D16="","",D16),IF(C16="","",C16)) -> 6.96 | H16: 1 | I16: =IF(OR(B16="",G16=""),"",G16-B16) -> 0.48 | J16: 20.82 | K16: =IF(COUNTIFS(Release_Calendar!$A$2:$A$755,"US_CPI",Release_Calendar!$B$2:$B$755,$A16)>0,1,0) -> 0 | L16: =IF(COUNTIFS(Release_Calendar!$A$2:$A$755,"US_NFP",Release_Calendar!$B$2:$B$755,$A16)>0,1,0) -> 0 | M16: =IF($A16<Notes!$B$5,"",IF(COUNTIFS(Release_Calendar!$A$2:$A$755,"NZ_CPI",Release_Calendar!$B$2:$B$755,$A16)>0,1,0)) | N16: =IF($A16<Notes!$B$5,"",IF(COUNTIFS(Release_Calendar!$A$2:$A$755,"NZ_GDP",Release_Calendar!$B$2:$B$755,$A16)>0,1,0)) | O16: =IF($A16<Notes!$B$5,"",IF(COUNTIFS(Release_Calendar!$A$2:$A$755,"NZ_LABOUR",Release_Calendar!$B$2:$B$755,$A16)>0,1,0)) | P16: =IF(SUM(K16:O16)>0,1,0) -> 0
A17: 36549 | B17: 6.43 | D17: 6.96 | F17: =IF(OR(B17="",C17=""),"",C17-B17) | G17: =IF(H17=1,IF(D17="","",D17),IF(C17="","",C17)) -> 6.96 | H17: 1 | I17: =IF(OR(B17="",G17=""),"",G17-B17) -> 0.53 | J17: 24.07 | K17: =IF(COUNTIFS(Release_Calendar!$A$2:$A$755,"US_CPI",Release_Calendar!$B$2:$B$755,$A17)>0,1,0) -> 0 | L17: =IF(COUNTIFS(Release_Calendar!$A$2:$A$755,"US_NFP",Release_Calendar!$B$2:$B$755,$A17)>0,1,0) -> 0 | M17: =IF($A17<Notes!$B$5,"",IF(COUNTIFS(Release_Calendar!$A$2:$A$755,"NZ_CPI",Release_Calendar!$B$2:$B$755,$A17)>0,1,0)) | N17: =IF($A17<Notes!$B$5,"",IF(COUNTIFS(Release_Calendar!$A$2:$A$755,"NZ_GDP",Release_Calendar!$B$2:$B$755,$A17)>0,1,0)) | O17: =IF($A17<Notes!$B$5,"",IF(COUNTIFS(Release_Calendar!$A$2:$A$755,"NZ_LABOUR",Release_Calendar!$B$2:$B$755,$A17)>0,1,0)) | P17: =IF(SUM(K17:O17)>0,1,0) -> 0
A18: 36550 | B18: 6.44 | D18: 6.96 | F18: =IF(OR(B18="",C18=""),"",C18-B18) | G18: =IF(H18=1,IF(D18="","",D18),IF(C18="","",C18)) -> 6.96 | H18: 1 | I18: =IF(OR(B18="",G18=""),"",G18-B18) -> 0.52 | J18: 23.02 | K18: =IF(COUNTIFS(Release_Calendar!$A$2:$A$755,"US_CPI",Release_Calendar!$B$2:$B$755,$A18)>0,1,0) -> 0 | L18: =IF(COUNTIFS(Release_Calendar!$A$2:$A$755,"US_NFP",Release_Calendar!$B$2:$B$755,$A18)>0,1,0) -> 0 | M18: =IF($A18<Notes!$B$5,"",IF(COUNTIFS(Release_Calendar!$A$2:$A$755,"NZ_CPI",Release_Calendar!$B$2:$B$755,$A18)>0,1,0)) | N18: =IF($A18<Notes!$B$5,"",IF(COUNTIFS(Release_Calendar!$A$2:$A$755,"NZ_GDP",Release_Calendar!$B$2:$B$755,$A18)>0,1,0)) | O18: =IF($A18<Notes!$B$5,"",IF(COUNTIFS(Release_Calendar!$A$2:$A$755,"NZ_LABOUR",Release_Calendar!$B$2:$B$755,$A18)>0,1,0)) | P18: =IF(SUM(K18:O18)>0,1,0) -> 0
A19: 36551 | B19: 6.45 | D19: 6.95 | F19: =IF(OR(B19="",C19=""),"",C19-B19) | G19: =IF(H19=1,IF(D19="","",D19),IF(C19="","",C19)) -> 6.95 | H19: 1 | I19: =IF(OR(B19="",G19=""),"",G19-B19) -> 0.5 | J19: 23.03 | K19: =IF(COUNTIFS(Release_Calendar!$A$2:$A$755,"US_CPI",Release_Calendar!$B$2:$B$755,$A19)>0,1,0) -> 0 | L19: =IF(COUNTIFS(Release_Calendar!$A$2:$A$755,"US_NFP",Release_Calendar!$B$2:$B$755,$A19)>0,1,0) -> 0 | M19: =IF($A19<Notes!$B$5,"",IF(COUNTIFS(Release_Calendar!$A$2:$A$755,"NZ_CPI",Release_Calendar!$B$2:$B$755,$A19)>0,1,0)) | N19: =IF($A19<Notes!$B$5,"",IF(COUNTIFS(Release_Calendar!$A$2:$A$755,"NZ_GDP",Release_Calendar!$B$2:$B$755,$A19)>0,1,0)) | O19: =IF($A19<Notes!$B$5,"",IF(COUNTIFS(Release_Calendar!$A$2:$A$755,"NZ_LABOUR",Release_Calendar!$B$2:$B$755,$A19)>0,1,0)) | P19: =IF(SUM(K19:O19)>0,1,0) -> 0
A20: 36552 | B20: 6.51 | D20: 6.91 | F20: =IF(OR(B20="",C20=""),"",C20-B20) | G20: =IF(H20=1,IF(D20="","",D20),IF(C20="","",C20)) -> 6.91 | H20: 1 | I20: =IF(OR(B20="",G20=""),"",G20-B20) -> 0.4 | J20: 23.54 | K20: =IF(COUNTIFS(Release_Calendar!$A$2:$A$755,"US_CPI",Release_Calendar!$B$2:$B$755,$A20)>0,1,0) -> 0 | L20: =IF(COUNTIFS(Release_Calendar!$A$2:$A$755,"US_NFP",Release_Calendar!$B$2:$B$755,$A20)>0,1,0) -> 0 | M20: =IF($A20<Notes!$B$5,"",IF(COUNTIFS(Release_Calendar!$A$2:$A$755,"NZ_CPI",Release_Calendar!$B$2:$B$755,$A20)>0,1,0)) | N20: =IF($A20<Notes!$B$5,"",IF(COUNTIFS(Release_Calendar!$A$2:$A$755,"NZ_GDP",Release_Calendar!$B$2:$B$755,$A20)>0,1,0)) | O20: =IF($A20<Notes!$B$5,"",IF(COUNTIFS(Release_Calendar!$A$2:$A$755,"NZ_LABOUR",Release_Calendar!$B$2:$B$755,$A20)>0,1,0)) | P20: =IF(SUM(K20:O20)>0,1,0) -> 0
A21: 36553 | B21: 6.58 | D21: 6.92 | F21: =IF(OR(B21="",C21=""),"",C21-B21) | G21: =IF(H21=1,IF(D21="","",D21),IF(C21="","",C21)) -> 6.92 | H21: 1 | I21: =IF(OR(B21="",G21=""),"",G21-B21) -> 0.34 | J21: 26.14 | K21: =IF(COUNTIFS(Release_Calendar!$A$2:$A$755,"US_CPI",Release_Calendar!$B$2:$B$755,$A21)>0,1,0) -> 0 | L21: =IF(COUNTIFS(Release_Calendar!$A$2:$A$755,"US_NFP",Release_Calendar!$B$2:$B$755,$A21)>0,1,0) -> 0 | M21: =IF($A21<Notes!$B$5,"",IF(COUNTIFS(Release_Calendar!$A$2:$A$755,"NZ_CPI",Release_Calendar!$B$2:$B$755,$A21)>0,1,0)) | N21: =IF($A21<Notes!$B$5,"",IF(COUNTIFS(Release_Calendar!$A$2:$A$755,"NZ_GDP",Release_Calendar!$B$2:$B$755,$A21)>0,1,0)) | O21: =IF($A21<Notes!$B$5,"",IF(COUNTIFS(Release_Calendar!$A$2:$A$755,"NZ_LABOUR",Release_Calendar!$B$2:$B$755,$A21)>0,1,0)) | P21: =IF(SUM(K21:O21)>0,1,0) -> 0
A22: 36556 | B22: 6.61 | D22: 7 | F22: =IF(OR(B22="",C22=""),"",C22-B22) | G22: =IF(H22=1,IF(D22="","",D22),IF(C22="","",C22)) -> 7 | H22: 1 | I22: =IF(OR(B22="",G22=""),"",G22-B22) -> 0.39 | J22: 24.95 | K22: =IF(COUNTIFS(Release_Calendar!$A$2:$A$755,"US_CPI",Release_Calendar!$B$2:$B$755,$A22)>0,1,0) -> 0 | L22: =IF(COUNTIFS(Release_Calendar!$A$2:$A$755,"US_NFP",Release_Calendar!$B$2:$B$755,$A22)>0,1,0) -> 0 | M22: =IF($A22<Notes!$B$5,"",IF(COUNTIFS(Release_Calendar!$A$2:$A$755,"NZ_CPI",Release_Calendar!$B$2:$B$755,$A22)>0,1,0)) | N22: =IF($A22<Notes!$B$5,"",IF(COUNTIFS(Release_Calendar!$A$2:$A$755,"NZ_GDP",Release_Calendar!$B$2:$B$755,$A22)>0,1,0)) | O22: =IF($A22<Notes!$B$5,"",IF(COUNTIFS(Release_Calendar!$A$2:$A$755,"NZ_LABOUR",Release_Calendar!$B$2:$B$755,$A22)>0,1,0)) | P22: =IF(SUM(K22:O22)>0,1,0) -> 0
A23: 36557 | B23: 6.6 | D23: 7.01 | F23: =IF(OR(B23="",C23=""),"",C23-B23) | G23: =IF(H23=1,IF(D23="","",D23),IF(C23="","",C23)) -> 7.01 | H23: 1 | I23: =IF(OR(B23="",G23=""),"",G23-B23) -> 0.41 | J23: 23.45 | K23: =IF(COUNTIFS(Release_Calendar!$A$2:$A$755,"US_CPI",Release_Calendar!$B$2:$B$755,$A23)>0,1,0) -> 0 | L23: =IF(COUNTIFS(Release_Calendar!$A$2:$A$755,"US_NFP",Release_Calendar!$B$2:$B$755,$A23)>0,1,0) -> 0 | M23: =IF($A23<Notes!$B$5,"",IF(COUNTIFS(Release_Calendar!$A$2:$A$755,"NZ_CPI",Release_Calendar!$B$2:$B$755,$A23)>0,1,0)) | N23: =IF($A23<Notes!$B$5,"",IF(COUNTIFS(Release_Calendar!$A$2:$A$755,"NZ_GDP",Release_Calendar!$B$2:$B$755,$A23)>0,1,0)) | O23: =IF($A23<Notes!$B$5,"",IF(COUNTIFS(Release_Calendar!$A$2:$A$755,"NZ_LABOUR",Release_Calendar!$B$2:$B$755,$A23)>0,1,0)) | P23: =IF(SUM(K23:O23)>0,1,0) -> 0
A24: 36558 | B24: 6.63 | D24: 7 | F24: =IF(OR(B24="",C24=""),"",C24-B24) | G24: =IF(H24=1,IF(D24="","",D24),IF(C24="","",C24)) -> 7 | H24: 1 | I24: =IF(OR(B24="",G24=""),"",G24-B24) -> 0.37 | J24: 23.12 | K24: =IF(COUNTIFS(Release_Calendar!$A$2:$A$755,"US_CPI",Release_Calendar!$B$2:$B$755,$A24)>0,1,0) -> 0 | L24: =IF(COUNTIFS(Release_Calendar!$A$2:$A$755,"US_NFP",Release_Calendar!$B$2:$B$755,$A24)>0,1,0) -> 0 | M24: =IF($A24<Notes!$B$5,"",IF(COUNTIFS(Release_Calendar!$A$2:$A$755,"NZ_CPI",Release_Calendar!$B$2:$B$755,$A24)>0,1,0)) | N24: =IF($A24<Notes!$B$5,"",IF(COUNTIFS(Release_Calendar!$A$2:$A$755,"NZ_GDP",Release_Calendar!$B$2:$B$755,$A24)>0,1,0)) | O24: =IF($A24<Notes!$B$5,"",IF(COUNTIFS(Release_Calendar!$A$2:$A$755,"NZ_LABOUR",Release_Calendar!$B$2:$B$755,$A24)>0,1,0)) | P24: =IF(SUM(K24:O24)>0,1,0) -> 0
... A36: 36574 | B36: 6.66 | D36: 7.07 | F36: =IF(OR(B36="",C36=""),"",C36-B36) | G36: =IF(H36=1,IF(D36="","",D36),IF(C36="","",C36)) -> 7.07 | H36: 1 | I36: =IF(OR(B36="",G36=""),"",G36-B36) -> 0.41 | J36: 26 | K36: =IF(COUNTIFS(Release_Calendar!$A$2:$A$755,"US_CPI",Release_Calendar!$B$2:$B$755,$A36)>0,1,0) -> 1 | L36: =IF(COUNTIFS(Release_Calendar!$A$2:$A$755,"US_NFP",Release_Calendar!$B$2:$B$755,$A36)>0,1,0) -> 0 | M36: =IF($A36<Notes!$B$5,"",IF(COUNTIFS(Release_Calendar!$A$2:$A$755,"NZ_CPI",Release_Calendar!$B$2:$B$755,$A36)>0,1,0)) | N36: =IF($A36<Notes!$B$5,"",IF(COUNTIFS(Release_Calendar!$A$2:$A$755,"NZ_GDP",Release_Calendar!$B$2:$B$755,$A36)>0,1,0)) | O36: =IF($A36<Notes!$B$5,"",IF(COUNTIFS(Release_Calendar!$A$2:$A$755,"NZ_LABOUR",Release_Calendar!$B$2:$B$755,$A36)>0,1,0)) | P36: =IF(SUM(K36:O36)>0,1,0) -> 1
A37: 36577 | D37: 7.03 | F37: =IF(OR(B37="",C37=""),"",C37-B37) | G37: =IF(H37=1,IF(D37="","",D37),IF(C37="","",C37)) -> 7.03 | H37: 1 | I37: =IF(OR(B37="",G37=""),"",G37-B37) | K37: =IF(COUNTIFS(Release_Calendar!$A$2:$A$755,"US_CPI",Release_Calendar!$B$2:$B$755,$A37)>0,1,0) -> 0 | L37: =IF(COUNTIFS(Release_Calendar!$A$2:$A$755,"US_NFP",Release_Calendar!$B$2:$B$755,$A37)>0,1,0) -> 0 | M37: =IF($A37<Notes!$B$5,"",IF(COUNTIFS(Release_Calendar!$A$2:$A$755,"NZ_CPI",Release_Calendar!$B$2:$B$755,$A37)>0,1,0)) | N37: =IF($A37<Notes!$B$5,"",IF(COUNTIFS(Release_Calendar!$A$2:$A$755,"NZ_GDP",Release_Calendar!$B$2:$B$755,$A37)>0,1,0)) | O37: =IF($A37<Notes!$B$5,"",IF(COUNTIFS(Release_Calendar!$A$2:$A$755,"NZ_LABOUR",Release_Calendar!$B$2:$B$755,$A37)>0,1,0)) | P37: =IF(SUM(K37:O37)>0,1,0) -> 0
A38: 36578 | B38: 6.57 | D38: 7.03 | F38: =IF(OR(B38="",C38=""),"",C38-B38) | G38: =IF(H38=1,IF(D38="","",D38),IF(C38="","",C38)) -> 7.03 | H38: 1 | I38: =IF(OR(B38="",G38=""),"",G38-B38) -> 0.46 | J38: 25.86 | K38: =IF(COUNTIFS(Release_Calendar!$A$2:$A$755,"US_CPI",Release_Calendar!$B$2:$B$755,$A38)>0,1,0) -> 0 | L38: =IF(COUNTIFS(Release_Calendar!$A$2:$A$755,"US_NFP",Release_Calendar!$B$2:$B$755,$A38)>0,1,0) -> 0 | M38: =IF($A38<Notes!$B$5,"",IF(COUNTIFS(Release_Calendar!$A$2:$A$755,"NZ_CPI",Release_Calendar!$B$2:$B$755,$A38)>0,1,0)) | N38: =IF($A38<Notes!$B$5,"",IF(COUNTIFS(Release_Calendar!$A$2:$A$755,"NZ_GDP",Release_Calendar!$B$2:$B$755,$A38)>0,1,0)) | O38: =IF($A38<Notes!$B$5,"",IF(COUNTIFS(Release_Calendar!$A$2:$A$755,"NZ_LABOUR",Release_Calendar!$B$2:$B$755,$A38)>0,1,0)) | P38: =IF(SUM(K38:O38)>0,1,0) -> 0
A39: 36579 | B39: 6.61 | D39: 6.98 | F39: =IF(OR(B39="",C39=""),"",C39-B39) | G39: =IF(H39=1,IF(D39="","",D39),IF(C39="","",C39)) -> 6.98 | H39: 1 | I39: =IF(OR(B39="",G39=""),"",G39-B39) -> 0.37 | J39: 23.89 | K39: =IF(COUNTIFS(Release_Calendar!$A$2:$A$755,"US_CPI",Release_Calendar!$B$2:$B$755,$A39)>0,1,0) -> 0 | L39: =IF(COUNTIFS(Release_Calendar!$A$2:$A$755,"US_NFP",Release_Calendar!$B$2:$B$755,$A39)>0,1,0) -> 0 | M39: =IF($A39<Notes!$B$5,"",IF(COUNTIFS(Release_Calendar!$A$2:$A$755,"NZ_CPI",Release_Calendar!$B$2:$B$755,$A39)>0,1,0)) | N39: =IF($A39<Notes!$B$5,"",IF(COUNTIFS(Release_Calendar!$A$2:$A$755,"NZ_GDP",Release_Calendar!$B$2:$B$755,$A39)>0,1,0)) | O39: =IF($A39<Notes!$B$5,"",IF(COUNTIFS(Release_Calendar!$A$2:$A$755,"NZ_LABOUR",Release_Calendar!$B$2:$B$755,$A39)>0,1,0)) | P39: =IF(SUM(K39:O39)>0,1,0) -> 0
A40: 36580 | B40: 6.52 | D40: 7.02 | F40: =IF(OR(B40="",C40=""),"",C40-B40) | G40: =IF(H40=1,IF(D40="","",D40),IF(C40="","",C40)) -> 7.02 | H40: 1 | I40: =IF(OR(B40="",G40=""),"",G40-B40) -> 0.5 | J40: 24.38 | K40: =IF(COUNTIFS(Release_Calendar!$A$2:$A$755,"US_CPI",Release_Calendar!$B$2:$B$755,$A40)>0,1,0) -> 0 | L40: =IF(COUNTIFS(Release_Calendar!$A$2:$A$755,"US_NFP",Release_Calendar!$B$2:$B$755,$A40)>0,1,0) -> 0 | M40: =IF($A40<Notes!$B$5,"",IF(COUNTIFS(Release_Calendar!$A$2:$A$755,"NZ_CPI",Release_Calendar!$B$2:$B$755,$A40)>0,1,0)) | N40: =IF($A40<Notes!$B$5,"",IF(COUNTIFS(Release_Calendar!$A$2:$A$755,"NZ_GDP",Release_Calendar!$B$2:$B$755,$A40)>0,1,0)) | O40: =IF($A40<Notes!$B$5,"",IF(COUNTIFS(Release_Calendar!$A$2:$A$755,"NZ_LABOUR",Release_Calendar!$B$2:$B$755,$A40)>0,1,0)) | P40: =IF(SUM(K40:O40)>0,1,0) -> 0
A41: 36581 | B41: 6.45 | D41: 7.01 | F41: =IF(OR(B41="",C41=""),"",C41-B41) | G41: =IF(H41=1,IF(D41="","",D41),IF(C41="","",C41)) -> 7.01 | H41: 1 | I41: =IF(OR(B41="",G41=""),"",G41-B41) -> 0.56 | J41: 25.2 | K41: =IF(COUNTIFS(Release_Calendar!$A$2:$A$755,"US_CPI",Release_Calendar!$B$2:$B$755,$A41)>0,1,0) -> 0 | L41: =IF(COUNTIFS(Release_Calendar!$A$2:$A$755,"US_NFP",Release_Calendar!$B$2:$B$755,$A41)>0,1,0) -> 0 | M41: =IF($A41<Notes!$B$5,"",IF(COUNTIFS(Release_Calendar!$A$2:$A$755,"NZ_CPI",Release_Calendar!$B$2:$B$755,$A41)>0,1,0)) | N41: =IF($A41<Notes!$B$5,"",IF(COUNTIFS(Release_Calendar!$A$2:$A$755,"NZ_GDP",Release_Calendar!$B$2:$B$755,$A41)>0,1,0)) | O41: =IF($A41<Notes!$B$5,"",IF(COUNTIFS(Release_Calendar!$A$2:$A$755,"NZ_LABOUR",Release_Calendar!$B$2:$B$755,$A41)>0,1,0)) | P41: =IF(SUM(K41:O41)>0,1,0) -> 0
A42: 36584 | B42: 6.47 | D42: 6.95 | F42: =IF(OR(B42="",C42=""),"",C42-B42) | G42: =IF(H42=1,IF(D42="","",D42),IF(C42="","",C42)) -> 6.95 | H42: 1 | I42: =IF(OR(B42="",G42=""),"",G42-B42) -> 0.48 | J42: 24.68 | K42: =IF(COUNTIFS(Release_Calendar!$A$2:$A$755,"US_CPI",Release_Calendar!$B$2:$B$755,$A42)>0,1,0) -> 0 | L42: =IF(COUNTIFS(Release_Calendar!$A$2:$A$755,"US_NFP",Release_Calendar!$B$2:$B$755,$A42)>0,1,0) -> 0 | M42: =IF($A42<Notes!$B$5,"",IF(COUNTIFS(Release_Calendar!$A$2:$A$755,"NZ_CPI",Release_Calendar!$B$2:$B$755,$A42)>0,1,0)) | N42: =IF($A42<Notes!$B$5,"",IF(COUNTIFS(Release_Calendar!$A$2:$A$755,"NZ_GDP",Release_Calendar!$B$2:$B$755,$A42)>0,1,0)) | O42: =IF($A42<Notes!$B$5,"",IF(COUNTIFS(Release_Calendar!$A$2:$A$755,"NZ_LABOUR",Release_Calendar!$B$2:$B$755,$A42)>0,1,0)) | P42: =IF(SUM(K42:O42)>0,1,0) -> 0
A43: 36585 | B43: 6.53 | D43: 7.03 | F43: =IF(OR(B43="",C43=""),"",C43-B43) | G43: =IF(H43=1,IF(D43="","",D43),IF(C43="","",C43)) -> 7.03 | H43: 1 | I43: =IF(OR(B43="",G43=""),"",G43-B43) -> 0.5 | J43: 23.37 | K43: =IF(COUNTIFS(Release_Calendar!$A$2:$A$755,"US_CPI",Release_Calendar!$B$2:$B$755,$A43)>0,1,0) -> 0 | L43: =IF(COUNTIFS(Release_Calendar!$A$2:$A$755,"US_NFP",Release_Calendar!$B$2:$B$755,$A43)>0,1,0) -> 0 | M43: =IF($A43<Notes!$B$5,"",IF(COUNTIFS(Release_Calendar!$A$2:$A$755,"NZ_CPI",Release_Calendar!$B$2:$B$755,$A43)>0,1,0)) | N43: =IF($A43<Notes!$B$5,"",IF(COUNTIFS(Release_Calendar!$A$2:$A$755,"NZ_GDP",Release_Calendar!$B$2:$B$755,$A43)>0,1,0)) | O43: =IF($A43<Notes!$B$5,"",IF(COUNTIFS(Release_Calendar!$A$2:$A$755,"NZ_LABOUR",Release_Calendar!$B$2:$B$755,$A43)>0,1,0)) | P43: =IF(SUM(K43:O43)>0,1,0) -> 0
A44: 36586 | B44: 6.52 | D44: 7.01 | F44: =IF(OR(B44="",C44=""),"",C44-B44) | G44: =IF(H44=1,IF(D44="","",D44),IF(C44="","",C44)) -> 7.01 | H44: 1 | I44: =IF(OR(B44="",G44=""),"",G44-B44) -> 0.49 | J44: 21.64 | K44: =IF(COUNTIFS(Release_Calendar!$A$2:$A$755,"US_CPI",Release_Calendar!$B$2:$B$755,$A44)>0,1,0) -> 0 | L44: =IF(COUNTIFS(Release_Calendar!$A$2:$A$755,"US_NFP",Release_Calendar!$B$2:$B$755,$A44)>0,1,0) -> 0 | M44: =IF($A44<Notes!$B$5,"",IF(COUNTIFS(Release_Calendar!$A$2:$A$755,"NZ_CPI",Release_Calendar!$B$2:$B$755,$A44)>0,1,0)) | N44: =IF($A44<Notes!$B$5,"",IF(COUNTIFS(Release_Calendar!$A$2:$A$755,"NZ_GDP",Release_Calendar!$B$2:$B$755,$A44)>0,1,0)) | O44: =IF($A44<Notes!$B$5,"",IF(COUNTIFS(Release_Calendar!$A$2:$A$755,"NZ_LABOUR",Release_Calendar!$B$2:$B$755,$A44)>0,1,0)) | P44: =IF(SUM(K44:O44)>0,1,0) -> 0
A45: 36587 | B45: 6.52 | D45: 6.98 | F45: =IF(OR(B45="",C45=""),"",C45-B45) | G45: =IF(H45=1,IF(D45="","",D45),IF(C45="","",C45)) -> 6.98 | H45: 1 | I45: =IF(OR(B45="",G45=""),"",G45-B45) -> 0.46 | J45: 21.06 | K45: =IF(COUNTIFS(Release_Calendar!$A$2:$A$755,"US_CPI",Release_Calendar!$B$2:$B$755,$A45)>0,1,0) -> 0 | L45: =IF(COUNTIFS(Release_Calendar!$A$2:$A$755,"US_NFP",Release_Calendar!$B$2:$B$755,$A45)>0,1,0) -> 0 | M45: =IF($A45<Notes!$B$5,"",IF(COUNTIFS(Release_Calendar!$A$2:$A$755,"NZ_CPI",Release_Calendar!$B$2:$B$755,$A45)>0,1,0)) | N45: =IF($A45<Notes!$B$5,"",IF(COUNTIFS(Release_Calendar!$A$2:$A$755,"NZ_GDP",Release_Calendar!$B$2:$B$755,$A45)>0,1,0)) | O45: =IF($A45<Notes!$B$5,"",IF(COUNTIFS(Release_Calendar!$A$2:$A$755,"NZ_LABOUR",Release_Calendar!$B$2:$B$755,$A45)>0,1,0)) | P45: =IF(SUM(K45:O45)>0,1,0) -> 0
A46: 36588 | B46: 6.5 | D46: 7 | F46: =IF(OR(B46="",C46=""),"",C46-B46) | G46: =IF(H46=1,IF(D46="","",D46),IF(C46="","",C46)) -> 7 | H46: 1 | I46: =IF(OR(B46="",G46=""),"",G46-B46) -> 0.5 | J46: 19.21 | K46: =IF(COUNTIFS(Release_Calendar!$A$2:$A$755,"US_CPI",Release_Calendar!$B$2:$B$755,$A46)>0,1,0) -> 0 | L46: =IF(COUNTIFS(Release_Calendar!$A$2:$A$755,"US_NFP",Release_Calendar!$B$2:$B$755,$A46)>0,1,0) -> 1 | M46: =IF($A46<Notes!$B$5,"",IF(COUNTIFS(Release_Calendar!$A$2:$A$755,"NZ_CPI",Release_Calendar!$B$2:$B$755,$A46)>0,1,0)) | N46: =IF($A46<Notes!$B$5,"",IF(COUNTIFS(Release_Calendar!$A$2:$A$755,"NZ_GDP",Release_Calendar!$B$2:$B$755,$A46)>0,1,0)) | O46: =IF($A46<Notes!$B$5,"",IF(COUNTIFS(Release_Calendar!$A$2:$A$755,"NZ_LABOUR",Release_Calendar!$B$2:$B$755,$A46)>0,1,0)) | P46: =IF(SUM(K46:O46)>0,1,0) -> 1
A47: 36591 | B47: 6.55 | D47: 6.98 | F47: =IF(OR(B47="",C47=""),"",C47-B47) | G47: =IF(H47=1,IF(D47="","",D47),IF(C47="","",C47)) -> 6.98 | H47: 1 | I47: =IF(OR(B47="",G47=""),"",G47-B47) -> 0.43 | J47: 21.5 | K47: =IF(COUNTIFS(Release_Calendar!$A$2:$A$755,"US_CPI",Release_Calendar!$B$2:$B$755,$A47)>0,1,0) -> 0 | L47: =IF(COUNTIFS(Release_Calendar!$A$2:$A$755,"US_NFP",Release_Calendar!$B$2:$B$755,$A47)>0,1,0) -> 0 | M47: =IF($A47<Notes!$B$5,"",IF(COUNTIFS(Release_Calendar!$A$2:$A$755,"NZ_CPI",Release_Calendar!$B$2:$B$755,$A47)>0,1,0)) | N47: =IF($A47<Notes!$B$5,"",IF(COUNTIFS(Release_Calendar!$A$2:$A$755,"NZ_GDP",Release_Calendar!$B$2:$B$755,$A47)>0,1,0)) | O47: =IF($A47<Notes!$B$5,"",IF(COUNTIFS(Release_Calendar!$A$2:$A$755,"NZ_LABOUR",Release_Calendar!$B$2:$B$755,$A47)>0,1,0)) | P47: =IF(SUM(K47:O47)>0,1,0) -> 0
A48: 36592 | B48: 6.48 | D48: 7.04 | F48: =IF(OR(B48="",C48=""),"",C48-B48) | G48: =IF(H48=1,IF(D48="","",D48),IF(C48="","",C48)) -> 7.04 | H48: 1 | I48: =IF(OR(B48="",G48=""),"",G48-B48) -> 0.56 | J48: 24.31 | K48: =IF(COUNTIFS(Release_Calendar!$A$2:$A$755,"US_CPI",Release_Calendar!$B$2:$B$755,$A48)>0,1,0) -> 0 | L48: =IF(COUNTIFS(Release_Calendar!$A$2:$A$755,"US_NFP",Release_Calendar!$B$2:$B$755,$A48)>0,1,0) -> 0 | M48: =IF($A48<Notes!$B$5,"",IF(COUNTIFS(Release_Calendar!$A$2:$A$755,"NZ_CPI",Release_Calendar!$B$2:$B$755,$A48)>0,1,0)) | N48: =IF($A48<Notes!$B$5,"",IF(COUNTIFS(Release_Calendar!$A$2:$A$755,"NZ_GDP",Release_Calendar!$B$2:$B$755,$A48)>0,1,0)) | O48: =IF($A48<Notes!$B$5,"",IF(COUNTIFS(Release_Calendar!$A$2:$A$755,"NZ_LABOUR",Release_Calendar!$B$2:$B$755,$A48)>0,1,0)) | P48: =IF(SUM(K48:O48)>0,1,0) -> 0
A49: 36593 | B49: 6.5 | D49: 7.01 | F49: =IF(OR(B49="",C49=""),"",C49-B49) | G49: =IF(H49=1,IF(D49="","",D49),IF(C49="","",C49)) -> 7.01 | H49: 1 | I49: =IF(OR(B49="",G49=""),"",G49-B49) -> 0.51 | J49: 23.82 | K49: =IF(COUNTIFS(Release_Calendar!$A$2:$A$755,"US_CPI",Release_Calendar!$B$2:$B$755,$A49)>0,1,0) -> 0 | L49: =IF(COUNTIFS(Release_Calendar!$A$2:$A$755,"US_NFP",Release_Calendar!$B$2:$B$755,$A49)>0,1,0) -> 0 | M49: =IF($A49<Notes!$B$5,"",IF(COUNTIFS(Release_Calendar!$A$2:$A$755,"NZ_CPI",Release_Calendar!$B$2:$B$755,$A49)>0,1,0)) | N49: =IF($A49<Notes!$B$5,"",IF(COUNTIFS(Release_Calendar!$A$2:$A$755,"NZ_GDP",Release_Calendar!$B$2:$B$755,$A49)>0,1,0)) | O49: =IF($A49<Notes!$B$5,"",IF(COUNTIFS(Release_Calendar!$A$2:$A$755,"NZ_LABOUR",Release_Calendar!$B$2:$B$755,$A49)>0,1,0)) | P49: =IF(SUM(K49:O49)>0,1,0) -> 0
... A80: 36636 | B80: 6.38 | D80: 6.8 | F80: =IF(OR(B80="",C80=""),"",C80-B80) | G80: =IF(H80=1,IF(D80="","",D80),IF(C80="","",C80)) -> 6.8 | H80: 1 | I80: =IF(OR(B80="",G80=""),"",G80-B80) -> 0.42 | J80: 25.85 | K80: =IF(COUNTIFS(Release_Calendar!$A$2:$A$755,"US_CPI",Release_Calendar!$B$2:$B$755,$A80)>0,1,0) -> 0 | L80: =IF(COUNTIFS(Release_Calendar!$A$2:$A$755,"US_NFP",Release_Calendar!$B$2:$B$755,$A80)>0,1,0) -> 0 | M80: =IF($A80<Notes!$B$5,"",IF(COUNTIFS(Release_Calendar!$A$2:$A$755,"NZ_CPI",Release_Calendar!$B$2:$B$755,$A80)>0,1,0)) | N80: =IF($A80<Notes!$B$5,"",IF(COUNTIFS(Release_Calendar!$A$2:$A$755,"NZ_GDP",Release_Calendar!$B$2:$B$755,$A80)>0,1,0)) | O80: =IF($A80<Notes!$B$5,"",IF(COUNTIFS(Release_Calendar!$A$2:$A$755,"NZ_LABOUR",Release_Calendar!$B$2:$B$755,$A80)>0,1,0)) | P80: =IF(SUM(K80:O80)>0,1,0) -> 0
A81: 36637 | F81: =IF(OR(B81="",C81=""),"",C81-B81) | G81: =IF(H81=1,IF(D81="","",D81),IF(C81="","",C81)) | H81: 1 | I81: =IF(OR(B81="",G81=""),"",G81-B81) | K81: =IF(COUNTIFS(Release_Calendar!$A$2:$A$755,"US_CPI",Release_Calendar!$B$2:$B$755,$A81)>0,1,0) -> 0 | L81: =IF(COUNTIFS(Release_Calendar!$A$2:$A$755,"US_NFP",Release_Calendar!$B$2:$B$755,$A81)>0,1,0) -> 0 | M81: =IF($A81<Notes!$B$5,"",IF(COUNTIFS(Release_Calendar!$A$2:$A$755,"NZ_CPI",Release_Calendar!$B$2:$B$755,$A81)>0,1,0)) | N81: =IF($A81<Notes!$B$5,"",IF(COUNTIFS(Release_Calendar!$A$2:$A$755,"NZ_GDP",Release_Calendar!$B$2:$B$755,$A81)>0,1,0)) | O81: =IF($A81<Notes!$B$5,"",IF(COUNTIFS(Release_Calendar!$A$2:$A$755,"NZ_LABOUR",Release_Calendar!$B$2:$B$755,$A81)>0,1,0)) | P81: =IF(SUM(K81:O81)>0,1,0) -> 0
...

Sheet Release_Calendar
A1: indicator | B1: local_release_date | C1: local_time | D1: time_zone | E1: release_time_utc | F1: release_time_new_york | G1: us_eastern_date | H1: reference_period | I1: source
A2: US_NFP | B2: 36532 | C2: 08:30 | D2: America/New_York | E2: 36532.562 | F2: 36532.354 | G2: 36532 | I2: ALFRED vintage dates for PAYEMS (St. Louis Fed)
A3: US_CPI | B3: 36539 | C3: 08:30 | D3: America/New_York | E3: 36539.562 | F3: 36539.354 | G3: 36539 | I3: ALFRED vintage dates for CPIAUCNS (St. Louis Fed)
A4: US_NFP | B4: 36560 | C4: 08:30 | D4: America/New_York | E4: 36560.562 | F4: 36560.354 | G4: 36560 | I4: ALFRED vintage dates for PAYEMS (St. Louis Fed)
A5: US_CPI | B5: 36574 | C5: 08:30 | D5: America/New_York | E5: 36574.562 | F5: 36574.354 | G5: 36574 | I5: ALFRED vintage dates for CPIAUCNS (St. Louis Fed)
A6: US_NFP | B6: 36588 | C6: 08:30 | D6: America/New_York | E6: 36588.562 | F6: 36588.354 | G6: 36588 | I6: ALFRED vintage dates for PAYEMS (St. Louis Fed)
A7: US_CPI | B7: 36602 | C7: 08:30 | D7: America/New_York | E7: 36602.562 | F7: 36602.354 | G7: 36602 | I7: ALFRED vintage dates for CPIAUCNS (St. Louis Fed)
A8: US_NFP | B8: 36623 | C8: 08:30 | D8: America/New_York | E8: 36623.521 | F8: 36623.354 | G8: 36623 | I8: ALFRED vintage dates for PAYEMS (St. Louis Fed)
A9: US_CPI | B9: 36630 | C9: 08:30 | D9: America/New_York | E9: 36630.521 | F9: 36630.354 | G9: 36630 | I9: ALFRED vintage dates for CPIAUCNS (St. Louis Fed)
A10: US_NFP | B10: 36651 | C10: 08:30 | D10: America/New_York | E10: 36651.521 | F10: 36651.354 | G10: 36651 | I10: ALFRED vintage dates for PAYEMS (St. Louis Fed)
A11: US_CPI | B11: 36662 | C11: 08:30 | D11: America/New_York | E11: 36662.521 | F11: 36662.354 | G11: 36662 | I11: ALFRED vintage dates for CPIAUCNS (St. Louis Fed)
A12: US_NFP | B12: 36679 | C12: 08:30 | D12: America/New_York | E12: 36679.521 | F12: 36679.354 | G12: 36679 | I12: ALFRED vintage dates for PAYEMS (St. Louis Fed)
A13: US_CPI | B13: 36691 | C13: 08:30 | D13: America/New_York | E13: 36691.521 | F13: 36691.354 | G13: 36691 | I13: ALFRED vintage dates for CPIAUCNS (St. Louis Fed)
... A421: US_CPI | B421: 42900 | C421: 08:30 | D421: America/New_York | E421: 42900.521 | F421: 42900.354 | G421: 42900 | I421: ALFRED vintage dates for CPIAUCNS (St. Louis Fed)
A422: NZ_GDP | B422: 42901 | C422: 10:45 | D422: Pacific/Auckland | E422: 42900.948 | F422: 42900.781 | G422: 42900 | H422: March 2017 quarter | I422: Stats NZ information releases (stats.govt.nz)
A423: US_NFP | B423: 42923 | C423: 08:30 | D423: America/New_York | E423: 42923.521 | F423: 42923.354 | G423: 42923 | I423: ALFRED vintage dates for PAYEMS (St. Louis Fed)
A424: US_CPI | B424: 42930 | C424: 08:30 | D424: America/New_York | E424: 42930.521 | F424: 42930.354 | G424: 42930 | I424: ALFRED vintage dates for CPIAUCNS (St. Louis Fed)
A425: NZ_CPI | B425: 42934 | C425: 10:45 | D425: Pacific/Auckland | E425: 42933.948 | F425: 42933.781 | G425: 42933 | H425: June 2017 quarter | I425: Stats NZ information releases (stats.govt.nz)
A426: NZ_LABOUR | B426: 42949 | C426: 10:45 | D426: Pacific/Auckland | E426: 42948.948 | F426: 42948.781 | G426: 42948 | H426: June 2017 quarter | I426: Stats NZ information releases (stats.govt.nz)
A427: US_NFP | B427: 42951 | C427: 08:30 | D427: America/New_York | E427: 42951.521 | F427: 42951.354 | G427: 42951 | I427: ALFRED vintage dates for PAYEMS (St. Louis Fed)
A428: US_CPI | B428: 42958 | C428: 08:30 | D428: America/New_York | E428: 42958.521 | F428: 42958.354 | G428: 42958 | I428: ALFRED vintage dates for CPIAUCNS (St. Louis Fed)
A429: US_NFP | B429: 42979 | C429: 08:30 | D429: America/New_York | E429: 42979.521 | F429: 42979.354 | G429: 42979 | I429: ALFRED vintage dates for PAYEMS (St. Louis Fed)
A430: US_CPI | B430: 42992 | C430: 08:30 | D430: America/New_York | E430: 42992.521 | F430: 42992.354 | G430: 42992 | I430: ALFRED vintage dates for CPIAUCNS (St. Louis Fed)
A431: NZ_GDP | B431: 42999 | C431: 10:45 | D431: Pacific/Auckland | E431: 42998.948 | F431: 42998.781 | G431: 42998 | H431: June 2017 quarter | I431: Stats NZ information releases (stats.govt.nz)
A432: US_NFP | B432: 43014 | C432: 08:30 | D432: America/New_York | E432: 43014.521 | F432: 43014.354 | G432: 43014 | I432: ALFRED vintage dates for PAYEMS (St. Louis Fed)
A433: US_CPI | B433: 43021 | C433: 08:30 | D433: America/New_York | E433: 43021.521 | F433: 43021.354 | G433: 43021 | I433: ALFRED vintage dates for CPIAUCNS (St. Louis Fed)
A434: NZ_CPI | B434: 43025 | C434: 10:45 | D434: Pacific/Auckland | E434: 43024.906 | F434: 43024.74 | G434: 43024 | H434: September 2017 quarter | I434: Stats NZ information releases (stats.govt.nz)
A435: NZ_LABOUR | B435: 43040 | C435: 10:45 | D435: Pacific/Auckland | E435: 43039.906 | F435: 43039.74 | G435: 43039 | H435: September 2017 quarter | I435: Stats NZ information releases (stats.govt.nz)
A436: US_NFP | B436: 43042 | C436: 08:30 | D436: America/New_York | E436: 43042.521 | F436: 43042.354 | G436: 43042 | I436: ALFRED vintage dates for PAYEMS (St. Louis Fed)
A437: US_CPI | B437: 43054 | C437: 08:30 | D437: America/New_York | E437: 43054.562 | F437: 43054.354 | G437: 43054 | I437: ALFRED vintage dates for CPIAUCNS (St. Louis Fed)
A438: US_NFP | B438: 43077 | C438: 08:30 | D438: America/New_York | E438: 43077.562 | F438: 43077.354 | G438: 43077 | I438: ALFRED vintage dates for PAYEMS (St. Louis Fed)
A439: US_CPI | B439: 43082 | C439: 08:30 | D439: America/New_York | E439: 43082.562 | F439: 43082.354 | G439: 43082 | I439: ALFRED vintage dates for CPIAUCNS (St. Louis Fed)
A440: NZ_GDP | B440: 43090 | C440: 10:45 | D440: Pacific/Auckland | E440: 43089.906 | F440: 43089.698 | G440: 43089 | H440: September 2017 quarter | I440: Stats NZ information releases (stats.govt.nz)
A441: US_NFP | B441: 43105 | C441: 08:30 | D441: America/New_York | E441: 43105.562 | F441: 43105.354 | G441: 43105 | I441: ALFRED vintage dates for PAYEMS (St. Louis Fed)
A442: US_CPI | B442: 43112 | C442: 08:30 | D442: America/New_York | E442: 43112.562 | F442: 43112.354 | G442: 43112 | I442: ALFRED vintage dates for CPIAUCNS (St. Louis Fed)
A443: NZ_CPI | B443: 43125 | C443: 10:45 | D443: Pacific/Auckland | E443: 43124.906 | F443: 43124.698 | G443: 43124 | H443: December 2017 quarter | I443: Stats NZ information releases (stats.govt.nz)
A444: US_NFP | B444: 43133 | C444: 08:30 | D444: America/New_York | E444: 43133.562 | F444: 43133.354 | G444: 43133 | I444: ALFRED vintage dates for PAYEMS (St. Louis Fed)
A445: NZ_LABOUR | B445: 43138 | C445: 10:45 | D445: Pacific/Auckland | E445: 43137.906 | F445: 43137.698 | G445: 43137 | H445: December 2017 quarter | I445: Stats NZ information releases (stats.govt.nz)
A446: US_CPI | B446: 43145 | C446: 08:30 | D446: America/New_York | E446: 43145.562 | F446: 43145.354 | G446: 43145 | I446: ALFRED vintage dates for CPIAUCNS (St. Louis Fed)
A447: US_NFP | B447: 43168 | C447: 08:30 | D447: America/New_York | E447: 43168.562 | F447: 43168.354 | G447: 43168 | I447: ALFRED vintage dates for PAYEMS (St. Louis Fed)
...

Sheet Splice_Check
A1: Overlap check for splicing NZ 2y government bond yield (pre-2011) with NZ 2y swap
A3: Overlap window | B3: 5 Jan 2011 to 29 Dec 2017 (both NZ series available)
A4: Days with both swap and govt 11am | B4: 1466
A5: Mean spread swap minus govt 11am (pp) | B5: 0.213
A6: Std dev of spread (pp) | B6: 0.136
A7: Min / max spread (pp) | B7: -0.27 / 0.55
A8: Level correlation swap vs govt 11am | B8: 0.963
A9: Daily-change correlation swap vs govt 11am | B9: 0.526
A10: Daily-change correlation swap vs govt close | B10: 0.778
A11: Spread at splice: 5 Jan 2011 (swap 3.78, govt 3.97) | B11: -0.19
A14: Spread by year (swap minus govt 11am, pp)
A15: year | B15: mean | C15: std dev | D15: days
A16: 2011 | B16: 0.126 | C16: 0.186 | D16: 252
A17: 2012 | B17: 0.149 | C17: 0.118 | D17: 251
A18: 2013 | B18: 0.375 | C18: 0.079 | D18: 200
A19: 2014 | B19: 0.275 | C19: 0.02 | D19: 11
A20: 2015 | B20: 0.291 | C20: 0.092 | D20: 251
A21: 2016 | B21: 0.176 | C21: 0.047 | D21: 251
A22: 2017 | B22: 0.192 | C22: 0.062 | D22: 250
