Workbook
Name _xlchart.v1.1: 'Calcs and Graphs'!$B$20:$BG$20
Name _xlchart.v1.0: 'Calcs and Graphs'!$B$19:$BG$19
Name _xlchart.v1.2: 'Calcs and Graphs'!$B$19:$BG$19
Name _xlchart.v1.3: 'Calcs and Graphs'!$B$20:$BG$20

Sheet raw_imf
A1: KEY | B1: DATASET | C1: SERIES_CODE | D1: OBS_MEASURE | E1: COUNTRY | F1: ACCOUNTING_ENTRY | G1: INDICATOR | H1: SECTOR | I1: COUNTERPART_SECTOR | J1: COUNTERPART_COUNTRY | K1: FREQUENCY | L1: SCALE | M1: 1997-S1 | N1: 1997-S2 | O1: 1998-S1 | P1: 1998-S2 | Q1: 1999-S1 | R1: 1999-S2 | S1: 2000-S1 | T1: 2000-S2 | U1: 2001-S1 | V1: 2001-S2 | W1: 2002-S1 | X1: 2002-S2 | Y1: 2003-S1 | Z1: 2003-S2 | AA1: 2004-S1 | AB1: 2004-S2 | AC1: 2005-S1 | AD1: 2005-S2 | AE1: 2006-S1 | AF1: 2006-S2 | AG1: 2007-S1 | AH1: 2007-S2 | AI1: 2008-S1 | AJ1: 2008-S2 | AK1: 2009-S1 | AL1: 2009-S2 | AM1: 2010-S1 | AN1: 2010-S2 | AO1: 2011-S1 | AP1: 2011-S2 | AQ1: 2012-S1 | AR1: 2012-S2 | AS1: 2013-S1 | AT1: 2013-S2 | AU1: 2014-S1 | AV1: 2014-S2 | AW1: 2015-S1 | AX1: 2015-S2 | AY1: 2016-S1 | AZ1: 2016-S2 | BA1: 2017-S1 | BB1: 2017-S2 | BC1: 2018-S1 | BD1: 2018-S2 | BE1: 2019-S1 | BF1: 2019-S2 | BG1: 2020-S1 | BH1: 2020-S2 | BI1: 2021-S1 | BJ1: 2021-S2 | BK1: 2022-S1 | BL1: 2022-S2 | BM1: 2023-S1 | BN1: 2023-S2 | BO1: 2024-S1 | BP1: 2024-S2 | BQ1: 2025-S1 | BR1: 2025-S2
A2: =F2&"|"&G2&"|"&J2&"|"&K2 -> Liabilities|Portfolio investment, Debt securities, Long-term, Positions|Mexico|Half-yearly, semester | B2: IMF.STA:PIP(5.0.0) | C2: NZL.L.P_F3_L_P_USD.S1.S1.MEX.S | D2: OBS_VALUE | E2: New Zealand | F2: Liabilities | G2: Portfolio investment, Debt securities, Long-term, Positions | H2: Total economy | I2: Total economy | J2: Mexico | K2: Half-yearly, semester | L2: Millions | BA2: 0.038095238
A3: =F3&"|"&G3&"|"&J3&"|"&K3 -> Liabilities|Portfolio investment, Debt securities, Long-term, Positions|Finland|Half-yearly, semester | B3: IMF.STA:PIP(5.0.0) | C3: NZL.L.P_F3_L_P_USD.S1.S1.FIN.S | D3: OBS_VALUE | E3: New Zealand | F3: Liabilities | G3: Portfolio investment, Debt securities, Long-term, Positions | H3: Total economy | I3: Total economy | J3: Finland | K3: Half-yearly, semester | L3: Millions
A4: =F4&"|"&G4&"|"&J4&"|"&K4 -> Liabilities|Portfolio investment, Debt securities, Long-term, Positions|Qatar|Half-yearly, semester | B4: IMF.STA:PIP(5.0.0) | C4: NZL.L.P_F3_L_P_USD.S1.S1.QAT.S | D4: OBS_VALUE | E4: New Zealand | F4: Liabilities | G4: Portfolio investment, Debt securities, Long-term, Positions | H4: Total economy | I4: Total economy | J4: Qatar | K4: Half-yearly, semester | L4: Millions | BI4: 0.0076976907 | BJ4: 0.0075152012 | BK4: 0.00683527 | BL4: 0.0069686411
A5: =F5&"|"&G5&"|"&J5&"|"&K5 -> Liabilities|Portfolio investment, Debt securities, Long-term, Positions|Liechtenstein, Principality of|Half-yearly, semester | B5: IMF.STA:PIP(5.0.0) | C5: NZL.L.P_F3_L_P_USD.S1.S1.LIE.S | D5: OBS_VALUE | E5: New Zealand | F5: Liabilities | G5: Portfolio investment, Debt securities, Long-term, Positions | H5: Total economy | I5: Total economy | J5: Liechtenstein, Principality of | K5: Half-yearly, semester | L5: Millions
A6: =F6&"|"&G6&"|"&J6&"|"&K6 -> Liabilities|Portfolio investment, Debt securities, Long-term, Positions|Turks and Caicos Islands|Half-yearly, semester | B6: IMF.STA:PIP(5.0.0) | C6: NZL.L.P_F3_L_P_USD.S1.S1.TCA.S | D6: OBS_VALUE | E6: New Zealand | F6: Liabilities | G6: Portfolio investment, Debt securities, Long-term, Positions | H6: Total economy | I6: Total economy | J6: Turks and Caicos Islands | K6: Half-yearly, semester | L6: Millions
A7: =F7&"|"&G7&"|"&J7&"|"&K7 -> Liabilities|Portfolio investment, Debt securities, Long-term, Positions|Croatia, Republic of|Half-yearly, semester | B7: IMF.STA:PIP(5.0.0) | C7: NZL.L.P_F3_L_P_USD.S1.S1.HRV.S | D7: OBS_VALUE | E7: New Zealand | F7: Liabilities | G7: Portfolio investment, Debt securities, Long-term, Positions | H7: Total economy | I7: Total economy | J7: Croatia, Republic of | K7: Half-yearly, semester | L7: Millions
A8: =F8&"|"&G8&"|"&J8&"|"&K8 -> Liabilities|Portfolio investment, Debt securities, Long-term, Positions|Sweden|Half-yearly, semester | B8: IMF.STA:PIP(5.0.0) | C8: NZL.L.P_F3_L_P_USD.S1.S1.SWE.S | D8: OBS_VALUE | E8: New Zealand | F8: Liabilities | G8: Portfolio investment, Debt securities, Long-term, Positions | H8: Total economy | I8: Total economy | J8: Sweden | K8: Half-yearly, semester | L8: Millions
A9: =F9&"|"&G9&"|"&J9&"|"&K9 -> Liabilities|Portfolio investment, Debt securities, Long-term, Positions|Gibraltar|Half-yearly, semester | B9: IMF.STA:PIP(5.0.0) | C9: NZL.L.P_F3_L_P_USD.S1.S1.GIB.S | D9: OBS_VALUE | E9: New Zealand | F9: Liabilities | G9: Portfolio investment, Debt securities, Long-term, Positions | H9: Total economy | I9: Total economy | J9: Gibraltar | K9: Half-yearly, semester | L9: Millions
A10: =F10&"|"&G10&"|"&J10&"|"&K10 -> Liabilities|Portfolio investment, Debt securities, Long-term, Positions|Libya|Half-yearly, semester | B10: IMF.STA:PIP(5.0.0) | C10: NZL.L.P_F3_L_P_USD.S1.S1.LBY.S | D10: OBS_VALUE | E10: New Zealand | F10: Liabilities | G10: Portfolio investment, Debt securities, Long-term, Positions | H10: Total economy | I10: Total economy | J10: Libya | K10: Half-yearly, semester | L10: Millions
A11: =F11&"|"&G11&"|"&J11&"|"&K11 -> Liabilities|Portfolio investment, Debt securities, Long-term, Positions|Naoero, Republic of|Half-yearly, semester | B11: IMF.STA:PIP(5.0.0) | C11: NZL.L.P_F3_L_P_USD.S1.S1.NRU.S | D11: OBS_VALUE | E11: New Zealand | F11: Liabilities | G11: Portfolio investment, Debt securities, Long-term, Positions | H11: Total economy | I11: Total economy | J11: Naoero, Republic of | K11: Half-yearly, semester | L11: Millions
A12: =F12&"|"&G12&"|"&J12&"|"&K12 -> Liabilities|Portfolio investment, Debt securities, Long-term, Positions|Zimbabwe|Half-yearly, semester | B12: IMF.STA:PIP(5.0.0) | C12: NZL.L.P_F3_L_P_USD.S1.S1.ZWE.S | D12: OBS_VALUE | E12: New Zealand | F12: Liabilities | G12: Portfolio investment, Debt securities, Long-term, Positions | H12: Total economy | I12: Total economy | J12: Zimbabwe | K12: Half-yearly, semester | L12: Millions
A13: =F13&"|"&G13&"|"&J13&"|"&K13 -> Liabilities|Portfolio investment, Debt securities, Long-term, Positions|Bulgaria|Half-yearly, semester | B13: IMF.STA:PIP(5.0.0) | C13: NZL.L.P_F3_L_P_USD.S1.S1.BGR.S | D13: OBS_VALUE | E13: New Zealand | F13: Liabilities | G13: Portfolio investment, Debt securities, Long-term, Positions | H13: Total economy | I13: Total economy | J13: Bulgaria | K13: Half-yearly, semester | L13: Millions
A14: =F14&"|"&G14&"|"&J14&"|"&K14 -> Liabilities|Portfolio investment, Debt securities, Long-term, Positions|Tonga|Half-yearly, semester | B14: IMF.STA:PIP(5.0.0) | C14: NZL.L.P_F3_L_P_USD.S1.S1.TON.S | D14: OBS_VALUE | E14: New Zealand | F14: Liabilities | G14: Portfolio investment, Debt securities, Long-term, Positions | H14: Total economy | I14: Total economy | J14: Tonga | K14: Half-yearly, semester | L14: Millions
A15: =F15&"|"&G15&"|"&J15&"|"&K15 -> Liabilities|Portfolio investment, Debt securities, Long-term, Positions|Iceland|Half-yearly, semester | B15: IMF.STA:PIP(5.0.0) | C15: NZL.L.P_F3_L_P_USD.S1.S1.ISL.S | D15: OBS_VALUE | E15: New Zealand | F15: Liabilities | G15: Portfolio investment, Debt securities, Long-term, Positions | H15: Total economy | I15: Total economy | J15: Iceland | K15: Half-yearly, semester | L15: Millions
A16: =F16&"|"&G16&"|"&J16&"|"&K16 -> Liabilities|Portfolio investment, Debt securities, Long-term, Positions|Greece|Half-yearly, semester | B16: IMF.STA:PIP(5.0.0) | C16: NZL.L.P_F3_L_P_USD.S1.S1.GRC.S | D16: OBS_VALUE | E16: New Zealand | F16: Liabilities | G16: Portfolio investment, Debt securities, Long-term, Positions | H16: Total economy | I16: Total economy | J16: Greece | K16: Half-yearly, semester | L16: Millions
... A23: =F23&"|"&G23&"|"&J23&"|"&K23 -> Liabilities|Portfolio investment, Debt securities, Long-term, Positions|Armenia, Republic of|Half-yearly, semester | B23: IMF.STA:PIP(5.0.0) | C23: NZL.L.P_F3_L_P_USD.S1.S1.ARM.S | D23: OBS_VALUE | E23: New Zealand | F23: Liabilities | G23: Portfolio investment, Debt securities, Long-term, Positions | H23: Total economy | I23: Total economy | J23: Armenia, Republic of | K23: Half-yearly, semester | L23: Millions
A24: =F24&"|"&G24&"|"&J24&"|"&K24 -> Liabilities|Portfolio investment, Debt securities, Long-term, Positions|Malta|Half-yearly, semester | B24: IMF.STA:PIP(5.0.0) | C24: NZL.L.P_F3_L_P_USD.S1.S1.MLT.S | D24: OBS_VALUE | E24: New Zealand | F24: Liabilities | G24: Portfolio investment, Debt securities, Long-term, Positions | H24: Total economy | I24: Total economy | J24: Malta | K24: Half-yearly, semester | L24: Millions | AZ24: 0.13727266 | BA24: 0.14578755 | BB24: 0.14833215 | BC24: 0.13953488 | BD24: 0.13426423
A25: =F25&"|"&G25&"|"&J25&"|"&K25 -> Liabilities|Portfolio investment, Debt securities, Long-term, Positions|Kenya|Half-yearly, semester | B25: IMF.STA:PIP(5.0.0) | C25: NZL.L.P_F3_L_P_USD.S1.S1.KEN.S | D25: OBS_VALUE | E25: New Zealand | F25: Liabilities | G25: Portfolio investment, Debt securities, Long-term, Positions | H25: Total economy | I25: Total economy | J25: Kenya | K25: Half-yearly, semester | L25: Millions | AZ25: 0.14911853 | BA25: 0.15677656 | BB25: 0.15188077 | BC25: 0.076845298 | BD25: 0.14366273
A26: =F26&"|"&G26&"|"&J26&"|"&K26 -> Liabilities|Portfolio investment, Debt securities, Long-term, Positions|Isle of Man|Half-yearly, semester | B26: IMF.STA:PIP(5.0.0) | C26: NZL.L.P_F3_L_P_USD.S1.S1.IMN.S | D26: OBS_VALUE | E26: New Zealand | F26: Liabilities | G26: Portfolio investment, Debt securities, Long-term, Positions | H26: Total economy | I26: Total economy | J26: Isle of Man | K26: Half-yearly, semester | L26: Millions
A27: =F27&"|"&G27&"|"&J27&"|"&K27 -> Liabilities|Portfolio investment, Debt securities, Long-term, Positions|American Samoa|Half-yearly, semester | B27: IMF.STA:PIP(5.0.0) | C27: NZL.L.P_F3_L_P_USD.S1.S1.ASM.S | D27: OBS_VALUE | E27: New Zealand | F27: Liabilities | G27: Portfolio investment, Debt securities, Long-term, Positions | H27: Total economy | I27: Total economy | J27: American Samoa | K27: Half-yearly, semester | L27: Millions
A28: =F28&"|"&G28&"|"&J28&"|"&K28 -> Liabilities|Portfolio investment, Debt securities, Long-term, Positions|Venezuela, República Bolivariana de|Half-yearly, semester | B28: IMF.STA:PIP(5.0.0) | C28: NZL.L.P_F3_L_P_USD.S1.S1.VEN.S | D28: OBS_VALUE | E28: New Zealand | F28: Liabilities | G28: Portfolio investment, Debt securities, Long-term, Positions | H28: Total economy | I28: Total economy | J28: Venezuela, República Bolivariana de | K28: Half-yearly, semester | L28: Millions
A29: =F29&"|"&G29&"|"&J29&"|"&K29 -> Liabilities|Portfolio investment, Debt securities, Long-term, Positions|Chile|Half-yearly, semester | B29: IMF.STA:PIP(5.0.0) | C29: NZL.L.P_F3_L_P_USD.S1.S1.CHL.S | D29: OBS_VALUE | E29: New Zealand | F29: Liabilities | G29: Portfolio investment, Debt securities, Long-term, Positions | H29: Total economy | I29: Total economy | J29: Chile | K29: Half-yearly, semester | L29: Millions
A30: =F30&"|"&G30&"|"&J30&"|"&K30 -> Liabilities|Portfolio investment, Debt securities, Long-term, Positions|Bangladesh|Half-yearly, semester | B30: IMF.STA:PIP(5.0.0) | C30: NZL.L.P_F3_L_P_USD.S1.S1.BGD.S | D30: OBS_VALUE | E30: New Zealand | F30: Liabilities | G30: Portfolio investment, Debt securities, Long-term, Positions | H30: Total economy | I30: Total economy | J30: Bangladesh | K30: Half-yearly, semester | L30: Millions
A31: =F31&"|"&G31&"|"&J31&"|"&K31 -> Liabilities|Portfolio investment, Debt securities, Long-term, Positions|Macao Special Administrative Region, People's Republic of China|Half-yearly, semester | B31: IMF.STA:PIP(5.0.0) | C31: NZL.L.P_F3_L_P_USD.S1.S1.MAC.S | D31: OBS_VALUE | E31: New Zealand | F31: Liabilities | G31: Portfolio investment, Debt securities, Long-term, Positions | H31: Total economy | I31: Total economy | J31: Macao Special Administrative Region, People's Republic of China | K31: Half-yearly, semester | L31: Millions
A32: =F32&"|"&G32&"|"&J32&"|"&K32 -> Liabilities|Portfolio investment, Debt securities, Long-term, Positions|International Organizations|Half-yearly, semester | B32: IMF.STA:PIP(5.0.0) | C32: NZL.L.P_F3_L_P_USD.S1.S1.TX091.S | D32: OBS_VALUE | E32: New Zealand | F32: Liabilities | G32: Portfolio investment, Debt securities, Long-term, Positions | H32: Total economy | I32: Total economy | J32: International Organizations | K32: Half-yearly, semester | L32: Millions | AN32: 0
A33: =F33&"|"&G33&"|"&J33&"|"&K33 -> Liabilities|Portfolio investment, Debt securities, Long-term, Positions|Brunei Darussalam|Half-yearly, semester | B33: IMF.STA:PIP(5.0.0) | C33: NZL.L.P_F3_L_P_USD.S1.S1.BRN.S | D33: OBS_VALUE | E33: New Zealand | F33: Liabilities | G33: Portfolio investment, Debt securities, Long-term, Positions | H33: Total economy | I33: Total economy | J33: Brunei Darussalam | K33: Half-yearly, semester | L33: Millions
A34: =F34&"|"&G34&"|"&J34&"|"&K34 -> Liabilities|Portfolio investment, Debt securities, Long-term, Positions|Andorra, Principality of|Half-yearly, semester | B34: IMF.STA:PIP(5.0.0) | C34: NZL.L.P_F3_L_P_USD.S1.S1.AND.S | D34: OBS_VALUE | E34: New Zealand | F34: Liabilities | G34: Portfolio investment, Debt securities, Long-term, Positions | H34: Total economy | I34: Total economy | J34: Andorra, Principality of | K34: Half-yearly, semester | L34: Millions
A35: =F35&"|"&G35&"|"&J35&"|"&K35 -> Liabilities|Portfolio investment, Debt securities, Long-term, Positions|Ukraine|Half-yearly, semester | B35: IMF.STA:PIP(5.0.0) | C35: NZL.L.P_F3_L_P_USD.S1.S1.UKR.S | D35: OBS_VALUE | E35: New Zealand | F35: Liabilities | G35: Portfolio investment, Debt securities, Long-term, Positions | H35: Total economy | I35: Total economy | J35: Ukraine | K35: Half-yearly, semester | L35: Millions
A36: =F36&"|"&G36&"|"&J36&"|"&K36 -> Liabilities|Portfolio investment, Debt securities, Long-term, Positions|Samoa|Half-yearly, semester | B36: IMF.STA:PIP(5.0.0) | C36: NZL.L.P_F3_L_P_USD.S1.S1.WSM.S | D36: OBS_VALUE | E36: New Zealand | F36: Liabilities | G36: Portfolio investment, Debt securities, Long-term, Positions | H36: Total economy | I36: Total economy | J36: Samoa | K36: Half-yearly, semester | L36: Millions
A37: =F37&"|"&G37&"|"&J37&"|"&K37 -> Liabilities|Portfolio investment, Debt securities, Long-term, Positions|Bahamas, The|Half-yearly, semester | B37: IMF.STA:PIP(5.0.0) | C37: NZL.L.P_F3_L_P_USD.S1.S1.BHS.S | D37: OBS_VALUE | E37: New Zealand | F37: Liabilities | G37: Portfolio investment, Debt securities, Long-term, Positions | H37: Total economy | I37: Total economy | J37: Bahamas, The | K37: Half-yearly, semester | L37: Millions
A38: =F38&"|"&G38&"|"&J38&"|"&K38 -> Liabilities|Portfolio investment, Debt securities, Long-term, Positions|Solomon Islands|Half-yearly, semester | B38: IMF.STA:PIP(5.0.0) | C38: NZL.L.P_F3_L_P_USD.S1.S1.SLB.S | D38: OBS_VALUE | E38: New Zealand | F38: Liabilities | G38: Portfolio investment, Debt securities, Long-term, Positions | H38: Total economy | I38: Total economy | J38: Solomon Islands | K38: Half-yearly, semester | L38: Millions
A39: =F39&"|"&G39&"|"&J39&"|"&K39 -> Liabilities|Portfolio investment, Debt securities, Long-term, Positions|Poland, Republic of|Half-yearly, semester | B39: IMF.STA:PIP(5.0.0) | C39: NZL.L.P_F3_L_P_USD.S1.S1.POL.S | D39: OBS_VALUE | E39: New Zealand | F39: Liabilities | G39: Portfolio investment, Debt securities, Long-term, Positions | H39: Total economy | I39: Total economy | J39: Poland, Republic of | K39: Half-yearly, semester | L39: Millions
A40: =F40&"|"&G40&"|"&J40&"|"&K40 -> Liabilities|Portfolio investment, Debt securities, Long-term, Positions|Türkiye, Republic of|Half-yearly, semester | B40: IMF.STA:PIP(5.0.0) | C40: NZL.L.P_F3_L_P_USD.S1.S1.TUR.S | D40: OBS_VALUE | E40: New Zealand | F40: Liabilities | G40: Portfolio investment, Debt securities, Long-term, Positions | H40: Total economy | I40: Total economy | J40: Türkiye, Republic of | K40: Half-yearly, semester | L40: Millions
A41: =F41&"|"&G41&"|"&J41&"|"&K41 -> Liabilities|Portfolio investment, Debt securities, Long-term, Positions|Bhutan|Half-yearly, semester | B41: IMF.STA:PIP(5.0.0) | C41: NZL.L.P_F3_L_P_USD.S1.S1.BTN.S | D41: OBS_VALUE | E41: New Zealand | F41: Liabilities | G41: Portfolio investment, Debt securities, Long-term, Positions | H41: Total economy | I41: Total economy | J41: Bhutan | K41: Half-yearly, semester | L41: Millions
A42: =F42&"|"&G42&"|"&J42&"|"&K42 -> Liabilities|Portfolio investment, Debt securities, Long-term, Positions|Vietnam|Half-yearly, semester | B42: IMF.STA:PIP(5.0.0) | C42: NZL.L.P_F3_L_P_USD.S1.S1.VNM.S | D42: OBS_VALUE | E42: New Zealand | F42: Liabilities | G42: Portfolio investment, Debt securities, Long-term, Positions | H42: Total economy | I42: Total economy | J42: Vietnam | K42: Half-yearly, semester | L42: Millions
A43: =F43&"|"&G43&"|"&J43&"|"&K43 -> Liabilities|Portfolio investment, Debt securities, Long-term, Positions|Pakistan|Half-yearly, semester | B43: IMF.STA:PIP(5.0.0) | C43: NZL.L.P_F3_L_P_USD.S1.S1.PAK.S | D43: OBS_VALUE | E43: New Zealand | F43: Liabilities | G43: Portfolio investment, Debt securities, Long-term, Positions | H43: Total economy | I43: Total economy | J43: Pakistan | K43: Half-yearly, semester | L43: Millions
A44: =F44&"|"&G44&"|"&J44&"|"&K44 -> Liabilities|Portfolio investment, Debt securities, Positions|Suriname|Half-yearly, semester | B44: IMF.STA:PIP(5.0.0) | C44: NZL.L.P_F3_P_USD.S1.S1.SUR.S | D44: OBS_VALUE | E44: New Zealand | F44: Liabilities | G44: Portfolio investment, Debt securities, Positions | H44: Total economy | I44: Total economy | J44: Suriname | K44: Half-yearly, semester | L44: Millions | AL44: 0 | BI44: 0 | BM44: 0 | BO44: 0
A45: =F45&"|"&G45&"|"&J45&"|"&K45 -> Liabilities|Portfolio investment, Debt securities, Positions|Grenada|Half-yearly, semester | B45: IMF.STA:PIP(5.0.0) | C45: NZL.L.P_F3_P_USD.S1.S1.GRD.S | D45: OBS_VALUE | E45: New Zealand | F45: Liabilities | G45: Portfolio investment, Debt securities, Positions | H45: Total economy | I45: Total economy | J45: Grenada | K45: Half-yearly, semester | L45: Millions | AL45: 0 | BI45: 0 | BM45: 0 | BO45: 0
A46: =F46&"|"&G46&"|"&J46&"|"&K46 -> Liabilities|Portfolio investment, Debt securities, Positions|St. Kitts and Nevis|Half-yearly, semester | B46: IMF.STA:PIP(5.0.0) | C46: NZL.L.P_F3_P_USD.S1.S1.KNA.S | D46: OBS_VALUE | E46: New Zealand | F46: Liabilities | G46: Portfolio investment, Debt securities, Positions | H46: Total economy | I46: Total economy | J46: St. Kitts and Nevis | K46: Half-yearly, semester | L46: Millions | AL46: 0 | BI46: 0 | BM46: 0 | BO46: 0
...

Sheet Calcs and Graphs
B1: 1997-S1 | C1: 1997-S2 | D1: 1998-S1 | E1: 1998-S2 | F1: 1999-S1 | G1: 1999-S2 | H1: 2000-S1 | I1: 2000-S2 | J1: 2001-S1 | K1: 2001-S2 | L1: 2002-S1 | M1: 2002-S2 | N1: 2003-S1 | O1: 2003-S2 | P1: 2004-S1 | Q1: 2004-S2 | R1: 2005-S1 | S1: 2005-S2 | T1: 2006-S1 | U1: 2006-S2 | V1: 2007-S1 | W1: 2007-S2 | X1: 2008-S1 | Y1: 2008-S2 | Z1: 2009-S1 | AA1: 2009-S2 | AB1: 2010-S1 | AC1: 2010-S2 | AD1: 2011-S1 | AE1: 2011-S2 | AF1: 2012-S1 | AG1: 2012-S2 | AH1: 2013-S1 | AI1: 2013-S2 | AJ1: 2014-S1 | AK1: 2014-S2 | AL1: 2015-S1 | AM1: 2015-S2 | AN1: 2016-S1 | AO1: 2016-S2 | AP1: 2017-S1 | AQ1: 2017-S2 | AR1: 2018-S1 | AS1: 2018-S2 | AT1: 2019-S1 | AU1: 2019-S2 | AV1: 2020-S1 | AW1: 2020-S2 | AX1: 2021-S1 | AY1: 2021-S2 | AZ1: 2022-S1 | BA1: 2022-S2 | BB1: 2023-S1 | BC1: 2023-S2 | BD1: 2024-S1 | BE1: 2024-S2 | BF1: 2025-S1 | BG1: 2025-S2
A2: HEADLINE: Debt securities, Positions (NZ-reported)
A3: World (row 320) | B3: =IF(raw_imf!M320="",NA(),raw_imf!M320) -> #N/A | C3: =IF(raw_imf!N320="",NA(),raw_imf!N320) -> #N/A | D3: =IF(raw_imf!O320="",NA(),raw_imf!O320) -> #N/A | E3: =IF(raw_imf!P320="",NA(),raw_imf!P320) -> #N/A | F3: =IF(raw_imf!Q320="",NA(),raw_imf!Q320) -> #N/A | G3: =IF(raw_imf!R320="",NA(),raw_imf!R320) -> #N/A | H3: =IF(raw_imf!S320="",NA(),raw_imf!S320) -> #N/A | I3: =IF(raw_imf!T320="",NA(),raw_imf!T320) -> #N/A | ... BG3: =IF(raw_imf!BR320="",NA(),raw_imf!BR320) -> 165011.17
A4: US (row 351) | B4: =IF(raw_imf!M351="",NA(),raw_imf!M351) -> #N/A | C4: =IF(raw_imf!N351="",NA(),raw_imf!N351) -> #N/A | D4: =IF(raw_imf!O351="",NA(),raw_imf!O351) -> #N/A | E4: =IF(raw_imf!P351="",NA(),raw_imf!P351) -> #N/A | F4: =IF(raw_imf!Q351="",NA(),raw_imf!Q351) -> #N/A | G4: =IF(raw_imf!R351="",NA(),raw_imf!R351) -> #N/A | H4: =IF(raw_imf!S351="",NA(),raw_imf!S351) -> #N/A | I4: =IF(raw_imf!T351="",NA(),raw_imf!T351) -> #N/A | ... BG4: =IF(raw_imf!BR351="",NA(),raw_imf!BR351) -> 38123.712
A5: Rest of World | B5: =B3-B4 -> #N/A | C5: =C3-C4 -> #N/A | D5: =D3-D4 -> #N/A | E5: =E3-E4 -> #N/A | F5: =F3-F4 -> #N/A | G5: =G3-G4 -> #N/A | H5: =H3-H4 -> #N/A | I5: =I3-I4 -> #N/A | ... BG5: =BG3-BG4 -> 126887.46
A6: Share US | B6: =B4/B3 -> #N/A | C6: =C4/C3 -> #N/A | D6: =D4/D3 -> #N/A | E6: =E4/E3 -> #N/A | F6: =F4/F3 -> #N/A | G6: =G4/G3 -> #N/A | H6: =H4/H3 -> #N/A | I6: =I4/I3 -> #N/A | ... BG6: =BG4/BG3 -> 0.23103716
A7: Share Rest of World | B7: =B5/B3 -> #N/A | C7: =C5/C3 -> #N/A | D7: =D5/D3 -> #N/A | E7: =E5/E3 -> #N/A | F7: =F5/F3 -> #N/A | G7: =G5/G3 -> #N/A | H7: =H5/H3 -> #N/A | I7: =I5/I3 -> #N/A | ... BG7: =BG5/BG3 -> 0.76896284
A8: Share Not Specified (row 383) | B8: =IF(raw_imf!M383="",NA(),raw_imf!M383)/B3 -> #N/A | C8: =IF(raw_imf!N383="",NA(),raw_imf!N383)/C3 -> #N/A | D8: =IF(raw_imf!O383="",NA(),raw_imf!O383)/D3 -> #N/A | E8: =IF(raw_imf!P383="",NA(),raw_imf!P383)/E3 -> #N/A | F8: =IF(raw_imf!Q383="",NA(),raw_imf!Q383)/F3 -> #N/A | G8: =IF(raw_imf!R383="",NA(),raw_imf!R383)/G3 -> #N/A | H8: =IF(raw_imf!S383="",NA(),raw_imf!S383)/H3 -> #N/A | I8: =IF(raw_imf!T383="",NA(),raw_imf!T383)/I3 -> #N/A | ... BG8: =IF(raw_imf!BR383="",NA(),raw_imf!BR383)/BG3 -> 0.40208665
A10: DERIVED: Positions, using counterparty information
A11: World (row 467) | B11: =IF(raw_imf!M467="",NA(),raw_imf!M467) -> #N/A | C11: =IF(raw_imf!N467="",NA(),raw_imf!N467) -> 10221.908 | D11: =IF(raw_imf!O467="",NA(),raw_imf!O467) -> #N/A | E11: =IF(raw_imf!P467="",NA(),raw_imf!P467) -> #N/A | F11: =IF(raw_imf!Q467="",NA(),raw_imf!Q467) -> #N/A | G11: =IF(raw_imf!R467="",NA(),raw_imf!R467) -> #N/A | H11: =IF(raw_imf!S467="",NA(),raw_imf!S467) -> #N/A | I11: =IF(raw_imf!T467="",NA(),raw_imf!T467) -> #N/A | ... BG11: =IF(raw_imf!BR467="",NA(),raw_imf!BR467) -> 89752.614
A12: US (row 468) | B12: =IF(raw_imf!M468="",NA(),raw_imf!M468) -> #N/A | C12: =IF(raw_imf!N468="",NA(),raw_imf!N468) -> 3469 | D12: =IF(raw_imf!O468="",NA(),raw_imf!O468) -> #N/A | E12: =IF(raw_imf!P468="",NA(),raw_imf!P468) -> #N/A | F12: =IF(raw_imf!Q468="",NA(),raw_imf!Q468) -> #N/A | G12: =IF(raw_imf!R468="",NA(),raw_imf!R468) -> #N/A | H12: =IF(raw_imf!S468="",NA(),raw_imf!S468) -> #N/A | I12: =IF(raw_imf!T468="",NA(),raw_imf!T468) -> #N/A | ... BG12: =IF(raw_imf!BR468="",NA(),raw_imf!BR468) -> 17327
A13: Rest of World | B13: =B11-B12 -> #N/A | C13: =C11-C12 -> 6752.9076 | D13: =D11-D12 -> #N/A | E13: =E11-E12 -> #N/A | F13: =F11-F12 -> #N/A | G13: =G11-G12 -> #N/A | H13: =H11-H12 -> #N/A | I13: =I11-I12 -> #N/A | ... BG13: =BG11-BG12 -> 72425.614
A14: Share US | B14: =B12/B11 -> #N/A | C14: =C12/C11 -> 0.33936914 | D14: =D12/D11 -> #N/A | E14: =E12/E11 -> #N/A | F14: =F12/F11 -> #N/A | G14: =G12/G11 -> #N/A | H14: =H12/H11 -> #N/A | I14: =I12/I11 -> #N/A | ... BG14: =BG12/BG11 -> 0.19305287
A15: Share Rest of World | B15: =B13/B11 -> #N/A | C15: =C13/C11 -> 0.66063086 | D15: =D13/D11 -> #N/A | E15: =E13/E11 -> #N/A | F15: =F13/F11 -> #N/A | G15: =G13/G11 -> #N/A | H15: =H13/H11 -> #N/A | I15: =I13/I11 -> #N/A | ... BG15: =BG13/BG11 -> 0.80694713
A17: New Zealand Announced Debt | B17: =B3 -> #N/A | C17: =C3 -> #N/A | D17: =D3 -> #N/A | E17: =E3 -> #N/A | F17: =F3 -> #N/A | G17: =G3 -> #N/A | H17: =H3 -> #N/A | I17: =I3 -> #N/A | ... BG17: =BG3 -> 165011.17
A18: US Treasuary Announced Debt to IMF (Backup is New Zealand guess) | B18: =IFERROR(B12,B4) -> #N/A | C18: =IFERROR(C12,C4) -> 3469 | D18: =IFERROR(D12,D4) -> #N/A | E18: =IFERROR(E12,E4) -> #N/A | F18: =IFERROR(F12,F4) -> #N/A | G18: =IFERROR(G12,G4) -> #N/A | H18: =IFERROR(H12,H4) -> #N/A | I18: =IFERROR(I12,I4) -> #N/A | ... BG18: =IFERROR(BG12,BG4) -> 17327
A19: Percentage US | B19: =B18/B17 -> #N/A | C19: =C18/C17 -> #N/A | D19: =D18/D17 -> #N/A | E19: =E18/E17 -> #N/A | F19: =F18/F17 -> #N/A | G19: =G18/G17 -> #N/A | H19: =H18/H17 -> #N/A | I19: =I18/I17 -> #N/A | ... BG19: =BG18/BG17 -> 0.10500501
A20: Percentage World | B20: =1-B19 -> #N/A | C20: =1-C19 -> #N/A | D20: =1-D19 -> #N/A | E20: =1-E19 -> #N/A | F20: =1-F19 -> #N/A | G20: =1-G19 -> #N/A | H20: =1-H19 -> #N/A | I20: =1-I19 -> #N/A | ... BG20: =1-BG19 -> 0.89499499
A22: RATIONALE

Sheet Intermediate Calcs
A1: date | B1: us_share
A2: {=TRANSPOSE(IF(ISBLANK('Calcs and Graphs'!AJ1:BG1), "", DATE(LEFT('Calcs and Graphs'!AJ1:BG1, 4), (RIGHT('Calcs and Graphs'!AJ1:BG1, 1) * 6) - 5, 1)))} -> 41640 | B2: {=TRANSPOSE('Calcs and Graphs'!AJ19:BG19)} -> 0.15802166
A3: 41821 | B3: 0.17697616
A4: 42005 | B4: 0.15258105
A5: 42186 | B5: 0.1597423
A6: 42370 | B6: 0.14949813
A7: 42552 | B7: 0.13364519
A8: 42736 | B8: 0.11804457
A9: 42917 | B9: 0.10106066
A10: 43101 | B10: 0.11602954
A11: 43282 | B11: 0.12425947
A12: 43466 | B12: 0.11809973
A13: 43647 | B13: 0.13588698
A14: 43831 | B14: 0.11752606
... A25: 45839 | B25: 0.10500501

Sheet Regression Series
A1: date | B1: us_share
A2: {=SEQUENCE(DATE(2026,1,1)-DATE(2014,1,1)+1,1,DATE(2014,1,1))} -> 41640 | B2: {=IF(ISBLANK(A2:A5158), "", VLOOKUP(A2:A5158, 'Intermediate Calcs'!A2:B25, 2, TRUE))} -> 0.15802166
A3: 41641 | B3: 0.15802166
A4: 41642 | B4: 0.15802166
A5: 41643 | B5: 0.15802166
A6: 41644 | B6: 0.15802166
A7: 41645 | B7: 0.15802166
A8: 41646 | B8: 0.15802166
A9: 41647 | B9: 0.15802166
A10: 41648 | B10: 0.15802166
A11: 41649 | B11: 0.15802166
A12: 41650 | B12: 0.15802166
A13: 41651 | B13: 0.15802166
A14: 41652 | B14: 0.15802166
... A4385: 46023 | B4385: 0.10500501
